 * Serving Flask app "chatbot" (lazy loading)
 * Environment: production
   WARNING: This is a development server. Do not use it in a production deployment.
   Use a production WSGI server instead.
 * Debug mode: off
 * Running on http://0.0.0.0:5000/ (Press CTRL+C to quit)
172.17.0.1 - - [01/Oct/2020 02:46:16] "[37mPOST /message HTTP/1.1[0m" 200 -
172.17.0.1 - - [01/Oct/2020 02:46:39] "[37mPOST /message HTTP/1.1[0m" 200 -
172.17.0.1 - - [01/Oct/2020 02:46:45] "[37mPOST /message HTTP/1.1[0m" 200 -
172.17.0.1 - - [01/Oct/2020 02:47:09] "[37mPOST /message HTTP/1.1[0m" 200 -
172.17.0.1 - - [01/Oct/2020 02:47:18] "[37mPOST /message HTTP/1.1[0m" 200 -
172.17.0.1 - - [01/Oct/2020 02:51:17] "[37mPOST /message HTTP/1.1[0m" 200 -
172.17.0.1 - - [01/Oct/2020 02:51:22] "[37mPOST /message HTTP/1.1[0m" 200 -
172.17.0.1 - - [01/Oct/2020 02:51:31] "[37mPOST /message HTTP/1.1[0m" 200 -
172.17.0.1 - - [01/Oct/2020 02:51:47] "[37mPOST /message HTTP/1.1[0m" 200 -
172.17.0.1 - - [01/Oct/2020 03:01:32] "[37mPOST /message HTTP/1.1[0m" 200 -
172.17.0.1 - - [01/Oct/2020 03:13:14] "[37mPOST /message HTTP/1.1[0m" 200 -
172.17.0.1 - - [01/Oct/2020 03:13:19] "[37mPOST /message HTTP/1.1[0m" 200 -
172.17.0.1 - - [01/Oct/2020 03:13:48] "[37mPOST /message HTTP/1.1[0m" 200 -
172.17.0.1 - - [01/Oct/2020 03:18:02] "[37mPOST /message HTTP/1.1[0m" 200 -
172.17.0.1 - - [01/Oct/2020 03:26:46] "[37mPOST /message HTTP/1.1[0m" 200 -
172.17.0.1 - - [01/Oct/2020 03:31:09] "[37mPOST /message HTTP/1.1[0m" 200 -
172.17.0.1 - - [01/Oct/2020 03:37:34] "[37mPOST /message HTTP/1.1[0m" 200 -
172.17.0.1 - - [01/Oct/2020 03:37:48] "[37mPOST /message HTTP/1.1[0m" 200 -
172.17.0.1 - - [01/Oct/2020 03:38:27] "[37mPOST /message HTTP/1.1[0m" 200 -
172.17.0.1 - - [01/Oct/2020 03:41:53] "[37mPOST /message HTTP/1.1[0m" 200 -
172.17.0.1 - - [01/Oct/2020 03:42:08] "[37mPOST /message HTTP/1.1[0m" 200 -
172.17.0.1 - - [01/Oct/2020 03:42:46] "[37mPOST /message HTTP/1.1[0m" 200 -
172.17.0.1 - - [01/Oct/2020 03:42:57] "[37mPOST /message HTTP/1.1[0m" 200 -
172.17.0.1 - - [01/Oct/2020 03:43:05] "[37mPOST /message HTTP/1.1[0m" 200 -
172.17.0.1 - - [01/Oct/2020 03:43:50] "[37mPOST /message HTTP/1.1[0m" 200 -
172.17.0.1 - - [01/Oct/2020 03:44:25] "[37mPOST /message HTTP/1.1[0m" 200 -
172.17.0.1 - - [01/Oct/2020 03:44:54] "[37mPOST /message HTTP/1.1[0m" 200 -
172.17.0.1 - - [01/Oct/2020 03:45:04] "[37mPOST /message HTTP/1.1[0m" 200 -
172.17.0.1 - - [01/Oct/2020 03:46:47] "[37mPOST /message HTTP/1.1[0m" 200 -
172.17.0.1 - - [01/Oct/2020 03:49:52] "[37mPOST /message HTTP/1.1[0m" 200 -
172.17.0.1 - - [01/Oct/2020 03:57:30] "[37mPOST /message HTTP/1.1[0m" 200 -
172.17.0.1 - - [01/Oct/2020 03:57:44] "[37mPOST /message HTTP/1.1[0m" 200 -
172.17.0.1 - - [01/Oct/2020 04:13:51] "[37mPOST /message HTTP/1.1[0m" 200 -
172.17.0.1 - - [01/Oct/2020 04:14:02] "[37mPOST /message HTTP/1.1[0m" 200 -
172.17.0.1 - - [01/Oct/2020 04:14:24] "[37mPOST /message HTTP/1.1[0m" 200 -
172.17.0.1 - - [01/Oct/2020 04:31:54] "[37mPOST /message HTTP/1.1[0m" 200 -
172.17.0.1 - - [01/Oct/2020 04:35:43] "[37mPOST /message HTTP/1.1[0m" 200 -
172.17.0.1 - - [01/Oct/2020 04:35:46] "[37mPOST /message HTTP/1.1[0m" 200 -
172.17.0.1 - - [01/Oct/2020 04:35:52] "[37mPOST /message HTTP/1.1[0m" 200 -
172.17.0.1 - - [01/Oct/2020 04:43:16] "[37mPOST /message HTTP/1.1[0m" 200 -
172.17.0.1 - - [01/Oct/2020 04:43:21] "[37mPOST /message HTTP/1.1[0m" 200 -
172.17.0.1 - - [01/Oct/2020 04:52:01] "[37mPOST /message HTTP/1.1[0m" 200 -
172.17.0.1 - - [01/Oct/2020 04:54:16] "[37mPOST /message HTTP/1.1[0m" 200 -
172.17.0.1 - - [01/Oct/2020 04:54:39] "[37mPOST /message HTTP/1.1[0m" 200 -
172.17.0.1 - - [01/Oct/2020 04:55:24] "[37mPOST /message HTTP/1.1[0m" 200 -
172.17.0.1 - - [01/Oct/2020 04:55:55] "[37mPOST /message HTTP/1.1[0m" 200 -
172.17.0.1 - - [01/Oct/2020 04:57:15] "[37mPOST /message HTTP/1.1[0m" 200 -
172.17.0.1 - - [01/Oct/2020 04:57:54] "[37mPOST /message HTTP/1.1[0m" 200 -
172.17.0.1 - - [01/Oct/2020 06:55:54] "[37mPOST /message HTTP/1.1[0m" 200 -
172.17.0.1 - - [01/Oct/2020 06:56:02] "[37mPOST /message HTTP/1.1[0m" 200 -
172.17.0.1 - - [01/Oct/2020 11:50:33] "[37mPOST /message HTTP/1.1[0m" 200 -
172.17.0.1 - - [01/Oct/2020 12:18:41] "[37mPOST /message HTTP/1.1[0m" 200 -
172.17.0.1 - - [01/Oct/2020 13:37:23] "[37mPOST /message HTTP/1.1[0m" 200 -
172.17.0.1 - - [01/Oct/2020 14:23:27] "[37mPOST /message HTTP/1.1[0m" 200 -
172.17.0.1 - - [01/Oct/2020 14:39:11] "[37mPOST /message HTTP/1.1[0m" 200 -
172.17.0.1 - - [01/Oct/2020 14:39:21] "[37mPOST /message HTTP/1.1[0m" 200 -
172.17.0.1 - - [01/Oct/2020 14:54:38] "[37mPOST /message HTTP/1.1[0m" 200 -
172.17.0.1 - - [01/Oct/2020 14:57:26] "[37mPOST /message HTTP/1.1[0m" 200 -
172.17.0.1 - - [01/Oct/2020 14:57:31] "[37mPOST /message HTTP/1.1[0m" 200 -
172.17.0.1 - - [01/Oct/2020 15:12:45] "[37mPOST /message HTTP/1.1[0m" 200 -
172.17.0.1 - - [01/Oct/2020 15:30:48] "[37mPOST /message HTTP/1.1[0m" 200 -
172.17.0.1 - - [01/Oct/2020 17:15:08] "[37mPOST /message HTTP/1.1[0m" 200 -
172.17.0.1 - - [01/Oct/2020 17:22:02] "[37mPOST /message HTTP/1.1[0m" 200 -
172.17.0.1 - - [01/Oct/2020 17:22:57] "[37mPOST /message HTTP/1.1[0m" 200 -
172.17.0.1 - - [01/Oct/2020 17:23:22] "[37mPOST /message HTTP/1.1[0m" 200 -
172.17.0.1 - - [01/Oct/2020 17:23:31] "[37mPOST /message HTTP/1.1[0m" 200 -
172.17.0.1 - - [01/Oct/2020 17:23:39] "[37mPOST /message HTTP/1.1[0m" 200 -
172.17.0.1 - - [01/Oct/2020 17:23:43] "[37mPOST /message HTTP/1.1[0m" 200 -
172.17.0.1 - - [01/Oct/2020 17:25:02] "[37mPOST /message HTTP/1.1[0m" 200 -
172.17.0.1 - - [01/Oct/2020 17:25:13] "[37mPOST /message HTTP/1.1[0m" 200 -
172.17.0.1 - - [01/Oct/2020 17:25:25] "[37mPOST /message HTTP/1.1[0m" 200 -
172.17.0.1 - - [01/Oct/2020 17:25:30] "[37mPOST /message HTTP/1.1[0m" 200 -
172.17.0.1 - - [01/Oct/2020 17:25:34] "[37mPOST /message HTTP/1.1[0m" 200 -
172.17.0.1 - - [01/Oct/2020 17:25:48] "[37mPOST /message HTTP/1.1[0m" 200 -
172.17.0.1 - - [01/Oct/2020 17:26:34] "[37mPOST /message HTTP/1.1[0m" 200 -
172.17.0.1 - - [01/Oct/2020 17:26:38] "[37mPOST /message HTTP/1.1[0m" 200 -
172.17.0.1 - - [01/Oct/2020 17:26:57] "[1m[31mGET /message HTTP/1.1[0m" 405 -
172.17.0.1 - - [01/Oct/2020 17:26:58] "[33mGET /favicon.ico HTTP/1.1[0m" 404 -
172.17.0.1 - - [01/Oct/2020 17:27:01] "[33mGET / HTTP/1.1[0m" 404 -
172.17.0.1 - - [01/Oct/2020 17:33:35] "[37mPOST /message HTTP/1.1[0m" 200 -
172.17.0.1 - - [01/Oct/2020 17:39:21] "[37mPOST /message HTTP/1.1[0m" 200 -
172.17.0.1 - - [01/Oct/2020 17:39:34] "[37mPOST /message HTTP/1.1[0m" 200 -
172.17.0.1 - - [01/Oct/2020 17:39:39] "[37mPOST /message HTTP/1.1[0m" 200 -
172.17.0.1 - - [01/Oct/2020 17:40:21] "[37mPOST /message HTTP/1.1[0m" 200 -
172.17.0.1 - - [01/Oct/2020 21:13:07] "[37mPOST /message HTTP/1.1[0m" 200 -
172.17.0.1 - - [01/Oct/2020 21:13:22] "[37mPOST /message HTTP/1.1[0m" 200 -
172.17.0.1 - - [01/Oct/2020 21:14:23] "[37mPOST /message HTTP/1.1[0m" 200 -
172.17.0.1 - - [01/Oct/2020 22:25:05] "[37mPOST /message HTTP/1.1[0m" 200 -
172.17.0.1 - - [02/Oct/2020 00:28:04] "[37mPOST /message HTTP/1.1[0m" 200 -
172.17.0.1 - - [02/Oct/2020 01:01:39] "[37mPOST /message HTTP/1.1[0m" 200 -
172.17.0.1 - - [02/Oct/2020 02:17:07] "[37mPOST /message HTTP/1.1[0m" 200 -
172.17.0.1 - - [02/Oct/2020 02:33:23] "[37mPOST /message HTTP/1.1[0m" 200 -
172.17.0.1 - - [02/Oct/2020 03:04:45] "[37mPOST /message HTTP/1.1[0m" 200 -
172.17.0.1 - - [02/Oct/2020 04:15:32] "[37mPOST /message HTTP/1.1[0m" 200 -
172.17.0.1 - - [02/Oct/2020 04:16:53] "[37mPOST /message HTTP/1.1[0m" 200 -
172.17.0.1 - - [02/Oct/2020 04:17:54] "[37mPOST /message HTTP/1.1[0m" 200 -
172.17.0.1 - - [02/Oct/2020 04:43:23] "[37mPOST /message HTTP/1.1[0m" 200 -
172.17.0.1 - - [02/Oct/2020 04:46:56] "[37mPOST /message HTTP/1.1[0m" 200 -
172.17.0.1 - - [02/Oct/2020 04:54:16] "[37mPOST /message HTTP/1.1[0m" 200 -
172.17.0.1 - - [02/Oct/2020 04:57:33] "[37mPOST /message HTTP/1.1[0m" 200 -
172.17.0.1 - - [02/Oct/2020 05:07:30] "[37mPOST /message HTTP/1.1[0m" 200 -
172.17.0.1 - - [02/Oct/2020 05:42:11] "[37mPOST /message HTTP/1.1[0m" 200 -
172.17.0.1 - - [02/Oct/2020 05:42:24] "[37mPOST /message HTTP/1.1[0m" 200 -
172.17.0.1 - - [02/Oct/2020 05:52:37] "[37mPOST /message HTTP/1.1[0m" 200 -
172.17.0.1 - - [02/Oct/2020 05:52:52] "[37mPOST /message HTTP/1.1[0m" 200 -
172.17.0.1 - - [02/Oct/2020 05:53:10] "[37mPOST /message HTTP/1.1[0m" 200 -
172.17.0.1 - - [02/Oct/2020 05:53:20] "[37mPOST /message HTTP/1.1[0m" 200 -
172.17.0.1 - - [02/Oct/2020 05:54:21] "[37mPOST /message HTTP/1.1[0m" 200 -
172.17.0.1 - - [02/Oct/2020 06:37:00] "[37mPOST /message HTTP/1.1[0m" 200 -
172.17.0.1 - - [02/Oct/2020 07:17:50] "[37mPOST /message HTTP/1.1[0m" 200 -
172.17.0.1 - - [02/Oct/2020 07:18:27] "[37mPOST /message HTTP/1.1[0m" 200 -
172.17.0.1 - - [02/Oct/2020 07:18:39] "[37mPOST /message HTTP/1.1[0m" 200 -
172.17.0.1 - - [02/Oct/2020 07:59:01] "[37mPOST /message HTTP/1.1[0m" 200 -
172.17.0.1 - - [02/Oct/2020 07:59:38] "[37mPOST /message HTTP/1.1[0m" 200 -
172.17.0.1 - - [02/Oct/2020 11:13:47] "[37mPOST /message HTTP/1.1[0m" 200 -
172.17.0.1 - - [02/Oct/2020 11:57:02] "[37mPOST /message HTTP/1.1[0m" 200 -
172.17.0.1 - - [02/Oct/2020 11:57:08] "[37mPOST /message HTTP/1.1[0m" 200 -
172.17.0.1 - - [02/Oct/2020 11:57:18] "[37mPOST /message HTTP/1.1[0m" 200 -
172.17.0.1 - - [02/Oct/2020 13:18:59] "[37mPOST /message HTTP/1.1[0m" 200 -
172.17.0.1 - - [02/Oct/2020 13:19:30] "[37mPOST /message HTTP/1.1[0m" 200 -
172.17.0.1 - - [02/Oct/2020 13:20:53] "[37mPOST /message HTTP/1.1[0m" 200 -
172.17.0.1 - - [02/Oct/2020 13:21:51] "[37mPOST /message HTTP/1.1[0m" 200 -
172.17.0.1 - - [03/Oct/2020 04:46:25] "[37mPOST /message HTTP/1.1[0m" 200 -
172.17.0.1 - - [03/Oct/2020 13:01:08] "[37mPOST /message HTTP/1.1[0m" 200 -
172.17.0.1 - - [03/Oct/2020 14:40:51] "[37mPOST /message HTTP/1.1[0m" 200 -
172.17.0.1 - - [03/Oct/2020 14:41:23] "[37mPOST /message HTTP/1.1[0m" 200 -
172.17.0.1 - - [03/Oct/2020 14:42:10] "[37mPOST /message HTTP/1.1[0m" 200 -
172.17.0.1 - - [03/Oct/2020 15:15:52] "[37mPOST /message HTTP/1.1[0m" 200 -
172.17.0.1 - - [04/Oct/2020 04:49:22] "[37mPOST /message HTTP/1.1[0m" 200 -
172.17.0.1 - - [04/Oct/2020 04:51:28] "[37mPOST /message HTTP/1.1[0m" 200 -
172.17.0.1 - - [04/Oct/2020 04:51:49] "[37mPOST /message HTTP/1.1[0m" 200 -
172.17.0.1 - - [04/Oct/2020 04:51:58] "[37mPOST /message HTTP/1.1[0m" 200 -
172.17.0.1 - - [04/Oct/2020 04:57:18] "[37mPOST /message HTTP/1.1[0m" 200 -
172.17.0.1 - - [04/Oct/2020 06:00:41] "[37mPOST /message HTTP/1.1[0m" 200 -
172.17.0.1 - - [04/Oct/2020 06:01:10] "[37mPOST /message HTTP/1.1[0m" 200 -
172.17.0.1 - - [04/Oct/2020 10:50:59] "[37mPOST /message HTTP/1.1[0m" 200 -
172.17.0.1 - - [04/Oct/2020 10:51:06] "[37mPOST /message HTTP/1.1[0m" 200 -
172.17.0.1 - - [04/Oct/2020 11:00:26] "[37mPOST /message HTTP/1.1[0m" 200 -
172.17.0.1 - - [05/Oct/2020 02:56:02] "[37mPOST /message HTTP/1.1[0m" 200 -
172.17.0.1 - - [05/Oct/2020 02:56:12] "[37mPOST /message HTTP/1.1[0m" 200 -
172.17.0.1 - - [05/Oct/2020 02:59:55] "[37mPOST /message HTTP/1.1[0m" 200 -
172.17.0.1 - - [05/Oct/2020 07:34:46] "[37mPOST /message HTTP/1.1[0m" 200 -
172.17.0.1 - - [05/Oct/2020 08:09:49] "[37mPOST /message HTTP/1.1[0m" 200 -
172.17.0.1 - - [05/Oct/2020 08:10:05] "[37mPOST /message HTTP/1.1[0m" 200 -
172.17.0.1 - - [06/Oct/2020 16:03:21] "[37mPOST /message HTTP/1.1[0m" 200 -
172.17.0.1 - - [07/Oct/2020 13:19:52] "[37mPOST /message HTTP/1.1[0m" 200 -
172.17.0.1 - - [07/Oct/2020 13:20:34] "[37mPOST /message HTTP/1.1[0m" 200 -
193.142.146.50 - - [07/Oct/2020 14:49:33] code 400, message Bad HTTP/0.9 request type ('\x03\x00\x00/*à\x00\x00\x00\x00\x00Cookie:')
193.142.146.50 - - [07/Oct/2020 14:49:33] "[1m[35m  /*à     Cookie: mstshash=Administr[0m" HTTPStatus.BAD_REQUEST -
193.142.146.50 - - [08/Oct/2020 13:20:56] code 400, message Bad HTTP/0.9 request type ('\x03\x00\x00/*à\x00\x00\x00\x00\x00Cookie:')
193.142.146.50 - - [08/Oct/2020 13:20:56] "[1m[35m  /*à     Cookie: mstshash=Administr[0m" HTTPStatus.BAD_REQUEST -
172.17.0.1 - - [08/Oct/2020 15:04:06] "[1m[31mGET /message HTTP/1.1[0m" 405 -
172.17.0.1 - - [08/Oct/2020 15:04:06] "[33mGET /favicon.ico HTTP/1.1[0m" 404 -
172.17.0.1 - - [08/Oct/2020 15:04:10] "[33mGET / HTTP/1.1[0m" 404 -
172.17.0.1 - - [08/Oct/2020 15:20:32] "[37mPOST /message HTTP/1.1[0m" 200 -
 * Serving Flask app "chatbot" (lazy loading)
 * Environment: production
   WARNING: This is a development server. Do not use it in a production deployment.
   Use a production WSGI server instead.
 * Debug mode: off
 * Running on http://0.0.0.0:5000/ (Press CTRL+C to quit)
172.17.0.1 - - [15/Oct/2020 08:40:40] "[37mPOST /message HTTP/1.1[0m" 200 -
172.17.0.1 - - [15/Oct/2020 08:40:43] "[37mPOST /message HTTP/1.1[0m" 200 -
[2020-10-15 10:37:35,275] ERROR in app: Exception on /message [POST]
Traceback (most recent call last):
  File "/usr/local/lib/python3.7/site-packages/flask/app.py", line 2446, in wsgi_app
    response = self.full_dispatch_request()
  File "/usr/local/lib/python3.7/site-packages/flask/app.py", line 1951, in full_dispatch_request
    rv = self.handle_user_exception(e)
  File "/usr/local/lib/python3.7/site-packages/flask/app.py", line 1820, in handle_user_exception
    reraise(exc_type, exc_value, tb)
  File "/usr/local/lib/python3.7/site-packages/flask/_compat.py", line 39, in reraise
    raise value
  File "/usr/local/lib/python3.7/site-packages/flask/app.py", line 1949, in full_dispatch_request
    rv = self.dispatch_request()
  File "/usr/local/lib/python3.7/site-packages/flask/app.py", line 1935, in dispatch_request
    return self.view_functions[rule.endpoint](**req.view_args)
  File "/workspace/whaaats_new/chatbot.py", line 18, in Message
    keyword.index(ascending=False)
TypeError: 'Int64Index' object is not callable
172.17.0.1 - - [15/Oct/2020 10:37:35] "[1m[35mPOST /message HTTP/1.1[0m" 500 -
172.17.0.1 - - [15/Oct/2020 10:39:14] "[37mPOST /message HTTP/1.1[0m" 200 -
172.17.0.1 - - [15/Oct/2020 10:39:17] "[37mPOST /message HTTP/1.1[0m" 200 -
[2020-10-15 10:39:30,748] ERROR in app: Exception on /message [POST]
Traceback (most recent call last):
  File "/usr/local/lib/python3.7/site-packages/flask/app.py", line 2446, in wsgi_app
    response = self.full_dispatch_request()
  File "/usr/local/lib/python3.7/site-packages/flask/app.py", line 1951, in full_dispatch_request
    rv = self.handle_user_exception(e)
  File "/usr/local/lib/python3.7/site-packages/flask/app.py", line 1820, in handle_user_exception
    reraise(exc_type, exc_value, tb)
  File "/usr/local/lib/python3.7/site-packages/flask/_compat.py", line 39, in reraise
    raise value
  File "/usr/local/lib/python3.7/site-packages/flask/app.py", line 1949, in full_dispatch_request
    rv = self.dispatch_request()
  File "/usr/local/lib/python3.7/site-packages/flask/app.py", line 1935, in dispatch_request
    return self.view_functions[rule.endpoint](**req.view_args)
  File "/workspace/whaaats_new/chatbot.py", line 18, in Message
    keyword.index(ascending=False)
TypeError: 'Int64Index' object is not callable
172.17.0.1 - - [15/Oct/2020 10:39:30] "[1m[35mPOST /message HTTP/1.1[0m" 500 -
172.17.0.1 - - [15/Oct/2020 10:39:40] "[37mPOST /message HTTP/1.1[0m" 200 -
[2020-10-15 10:39:45,285] ERROR in app: Exception on /message [POST]
Traceback (most recent call last):
  File "/usr/local/lib/python3.7/site-packages/flask/app.py", line 2446, in wsgi_app
    response = self.full_dispatch_request()
  File "/usr/local/lib/python3.7/site-packages/flask/app.py", line 1951, in full_dispatch_request
    rv = self.handle_user_exception(e)
  File "/usr/local/lib/python3.7/site-packages/flask/app.py", line 1820, in handle_user_exception
    reraise(exc_type, exc_value, tb)
  File "/usr/local/lib/python3.7/site-packages/flask/_compat.py", line 39, in reraise
    raise value
  File "/usr/local/lib/python3.7/site-packages/flask/app.py", line 1949, in full_dispatch_request
    rv = self.dispatch_request()
  File "/usr/local/lib/python3.7/site-packages/flask/app.py", line 1935, in dispatch_request
    return self.view_functions[rule.endpoint](**req.view_args)
  File "/workspace/whaaats_new/chatbot.py", line 18, in Message
    keyword.index(ascending=False)
TypeError: 'Int64Index' object is not callable
172.17.0.1 - - [15/Oct/2020 10:39:45] "[1m[35mPOST /message HTTP/1.1[0m" 500 -
172.17.0.1 - - [15/Oct/2020 10:39:49] "[37mPOST /message HTTP/1.1[0m" 200 -
[2020-10-15 10:39:53,655] ERROR in app: Exception on /message [POST]
Traceback (most recent call last):
  File "/usr/local/lib/python3.7/site-packages/flask/app.py", line 2446, in wsgi_app
    response = self.full_dispatch_request()
  File "/usr/local/lib/python3.7/site-packages/flask/app.py", line 1951, in full_dispatch_request
    rv = self.handle_user_exception(e)
  File "/usr/local/lib/python3.7/site-packages/flask/app.py", line 1820, in handle_user_exception
    reraise(exc_type, exc_value, tb)
  File "/usr/local/lib/python3.7/site-packages/flask/_compat.py", line 39, in reraise
    raise value
  File "/usr/local/lib/python3.7/site-packages/flask/app.py", line 1949, in full_dispatch_request
    rv = self.dispatch_request()
  File "/usr/local/lib/python3.7/site-packages/flask/app.py", line 1935, in dispatch_request
    return self.view_functions[rule.endpoint](**req.view_args)
  File "/workspace/whaaats_new/chatbot.py", line 18, in Message
    keyword.index(ascending=False)
TypeError: 'Int64Index' object is not callable
172.17.0.1 - - [15/Oct/2020 10:39:53] "[1m[35mPOST /message HTTP/1.1[0m" 500 -
[2020-10-15 10:40:00,594] ERROR in app: Exception on /message [POST]
Traceback (most recent call last):
  File "/usr/local/lib/python3.7/site-packages/flask/app.py", line 2446, in wsgi_app
    response = self.full_dispatch_request()
  File "/usr/local/lib/python3.7/site-packages/flask/app.py", line 1951, in full_dispatch_request
    rv = self.handle_user_exception(e)
  File "/usr/local/lib/python3.7/site-packages/flask/app.py", line 1820, in handle_user_exception
    reraise(exc_type, exc_value, tb)
  File "/usr/local/lib/python3.7/site-packages/flask/_compat.py", line 39, in reraise
    raise value
  File "/usr/local/lib/python3.7/site-packages/flask/app.py", line 1949, in full_dispatch_request
    rv = self.dispatch_request()
  File "/usr/local/lib/python3.7/site-packages/flask/app.py", line 1935, in dispatch_request
    return self.view_functions[rule.endpoint](**req.view_args)
  File "/workspace/whaaats_new/chatbot.py", line 18, in Message
    keyword.index(ascending=False)
TypeError: 'Int64Index' object is not callable
172.17.0.1 - - [15/Oct/2020 10:40:00] "[1m[35mPOST /message HTTP/1.1[0m" 500 -
172.17.0.1 - - [15/Oct/2020 10:40:06] "[37mPOST /message HTTP/1.1[0m" 200 -
172.17.0.1 - - [15/Oct/2020 10:40:11] "[37mPOST /message HTTP/1.1[0m" 200 -
172.17.0.1 - - [15/Oct/2020 10:40:15] "[37mPOST /message HTTP/1.1[0m" 200 -
[2020-10-15 10:40:20,095] ERROR in app: Exception on /message [POST]
Traceback (most recent call last):
  File "/usr/local/lib/python3.7/site-packages/flask/app.py", line 2446, in wsgi_app
    response = self.full_dispatch_request()
  File "/usr/local/lib/python3.7/site-packages/flask/app.py", line 1951, in full_dispatch_request
    rv = self.handle_user_exception(e)
  File "/usr/local/lib/python3.7/site-packages/flask/app.py", line 1820, in handle_user_exception
    reraise(exc_type, exc_value, tb)
  File "/usr/local/lib/python3.7/site-packages/flask/_compat.py", line 39, in reraise
    raise value
  File "/usr/local/lib/python3.7/site-packages/flask/app.py", line 1949, in full_dispatch_request
    rv = self.dispatch_request()
  File "/usr/local/lib/python3.7/site-packages/flask/app.py", line 1935, in dispatch_request
    return self.view_functions[rule.endpoint](**req.view_args)
  File "/workspace/whaaats_new/chatbot.py", line 18, in Message
    keyword.index(ascending=False)
TypeError: 'Int64Index' object is not callable
172.17.0.1 - - [15/Oct/2020 10:40:20] "[1m[35mPOST /message HTTP/1.1[0m" 500 -
172.17.0.1 - - [15/Oct/2020 10:40:44] "[37mPOST /message HTTP/1.1[0m" 200 -
172.17.0.1 - - [15/Oct/2020 10:40:49] "[37mPOST /message HTTP/1.1[0m" 200 -
[2020-10-15 10:40:53,630] ERROR in app: Exception on /message [POST]
Traceback (most recent call last):
  File "/usr/local/lib/python3.7/site-packages/flask/app.py", line 2446, in wsgi_app
    response = self.full_dispatch_request()
  File "/usr/local/lib/python3.7/site-packages/flask/app.py", line 1951, in full_dispatch_request
    rv = self.handle_user_exception(e)
  File "/usr/local/lib/python3.7/site-packages/flask/app.py", line 1820, in handle_user_exception
    reraise(exc_type, exc_value, tb)
  File "/usr/local/lib/python3.7/site-packages/flask/_compat.py", line 39, in reraise
    raise value
  File "/usr/local/lib/python3.7/site-packages/flask/app.py", line 1949, in full_dispatch_request
    rv = self.dispatch_request()
  File "/usr/local/lib/python3.7/site-packages/flask/app.py", line 1935, in dispatch_request
    return self.view_functions[rule.endpoint](**req.view_args)
  File "/workspace/whaaats_new/chatbot.py", line 18, in Message
    keyword.index(ascending=False)
TypeError: 'Int64Index' object is not callable
172.17.0.1 - - [15/Oct/2020 10:40:53] "[1m[35mPOST /message HTTP/1.1[0m" 500 -
[2020-10-15 10:40:58,603] ERROR in app: Exception on /message [POST]
Traceback (most recent call last):
  File "/usr/local/lib/python3.7/site-packages/flask/app.py", line 2446, in wsgi_app
    response = self.full_dispatch_request()
  File "/usr/local/lib/python3.7/site-packages/flask/app.py", line 1951, in full_dispatch_request
    rv = self.handle_user_exception(e)
  File "/usr/local/lib/python3.7/site-packages/flask/app.py", line 1820, in handle_user_exception
    reraise(exc_type, exc_value, tb)
  File "/usr/local/lib/python3.7/site-packages/flask/_compat.py", line 39, in reraise
    raise value
  File "/usr/local/lib/python3.7/site-packages/flask/app.py", line 1949, in full_dispatch_request
    rv = self.dispatch_request()
  File "/usr/local/lib/python3.7/site-packages/flask/app.py", line 1935, in dispatch_request
    return self.view_functions[rule.endpoint](**req.view_args)
  File "/workspace/whaaats_new/chatbot.py", line 18, in Message
    keyword.index(ascending=False)
TypeError: 'Int64Index' object is not callable
172.17.0.1 - - [15/Oct/2020 10:40:58] "[1m[35mPOST /message HTTP/1.1[0m" 500 -
172.17.0.1 - - [15/Oct/2020 10:41:43] "[37mPOST /message HTTP/1.1[0m" 200 -
[2020-10-15 10:41:48,620] ERROR in app: Exception on /message [POST]
Traceback (most recent call last):
  File "/usr/local/lib/python3.7/site-packages/flask/app.py", line 2446, in wsgi_app
    response = self.full_dispatch_request()
  File "/usr/local/lib/python3.7/site-packages/flask/app.py", line 1951, in full_dispatch_request
    rv = self.handle_user_exception(e)
  File "/usr/local/lib/python3.7/site-packages/flask/app.py", line 1820, in handle_user_exception
    reraise(exc_type, exc_value, tb)
  File "/usr/local/lib/python3.7/site-packages/flask/_compat.py", line 39, in reraise
    raise value
  File "/usr/local/lib/python3.7/site-packages/flask/app.py", line 1949, in full_dispatch_request
    rv = self.dispatch_request()
  File "/usr/local/lib/python3.7/site-packages/flask/app.py", line 1935, in dispatch_request
    return self.view_functions[rule.endpoint](**req.view_args)
  File "/workspace/whaaats_new/chatbot.py", line 18, in Message
    keyword.index(ascending=False)
TypeError: 'Int64Index' object is not callable
172.17.0.1 - - [15/Oct/2020 10:41:48] "[1m[35mPOST /message HTTP/1.1[0m" 500 -
[2020-10-15 10:45:05,750] ERROR in app: Exception on /message [POST]
Traceback (most recent call last):
  File "/usr/local/lib/python3.7/site-packages/flask/app.py", line 2446, in wsgi_app
    response = self.full_dispatch_request()
  File "/usr/local/lib/python3.7/site-packages/flask/app.py", line 1951, in full_dispatch_request
    rv = self.handle_user_exception(e)
  File "/usr/local/lib/python3.7/site-packages/flask/app.py", line 1820, in handle_user_exception
    reraise(exc_type, exc_value, tb)
  File "/usr/local/lib/python3.7/site-packages/flask/_compat.py", line 39, in reraise
    raise value
  File "/usr/local/lib/python3.7/site-packages/flask/app.py", line 1949, in full_dispatch_request
    rv = self.dispatch_request()
  File "/usr/local/lib/python3.7/site-packages/flask/app.py", line 1935, in dispatch_request
    return self.view_functions[rule.endpoint](**req.view_args)
  File "/workspace/whaaats_new/chatbot.py", line 18, in Message
    keyword.index(ascending=False)
TypeError: 'Int64Index' object is not callable
172.17.0.1 - - [15/Oct/2020 10:45:05] "[1m[35mPOST /message HTTP/1.1[0m" 500 -
172.17.0.1 - - [15/Oct/2020 10:45:12] "[37mPOST /message HTTP/1.1[0m" 200 -
[2020-10-15 10:46:09,093] ERROR in app: Exception on /message [POST]
Traceback (most recent call last):
  File "/usr/local/lib/python3.7/site-packages/flask/app.py", line 2446, in wsgi_app
    response = self.full_dispatch_request()
  File "/usr/local/lib/python3.7/site-packages/flask/app.py", line 1951, in full_dispatch_request
    rv = self.handle_user_exception(e)
  File "/usr/local/lib/python3.7/site-packages/flask/app.py", line 1820, in handle_user_exception
    reraise(exc_type, exc_value, tb)
  File "/usr/local/lib/python3.7/site-packages/flask/_compat.py", line 39, in reraise
    raise value
  File "/usr/local/lib/python3.7/site-packages/flask/app.py", line 1949, in full_dispatch_request
    rv = self.dispatch_request()
  File "/usr/local/lib/python3.7/site-packages/flask/app.py", line 1935, in dispatch_request
    return self.view_functions[rule.endpoint](**req.view_args)
  File "/workspace/whaaats_new/chatbot.py", line 18, in Message
    keyword.index(ascending=False)
TypeError: 'Int64Index' object is not callable
172.17.0.1 - - [15/Oct/2020 10:46:09] "[1m[35mPOST /message HTTP/1.1[0m" 500 -
[2020-10-15 10:46:21,057] ERROR in app: Exception on /message [POST]
Traceback (most recent call last):
  File "/usr/local/lib/python3.7/site-packages/flask/app.py", line 2446, in wsgi_app
    response = self.full_dispatch_request()
  File "/usr/local/lib/python3.7/site-packages/flask/app.py", line 1951, in full_dispatch_request
    rv = self.handle_user_exception(e)
  File "/usr/local/lib/python3.7/site-packages/flask/app.py", line 1820, in handle_user_exception
    reraise(exc_type, exc_value, tb)
  File "/usr/local/lib/python3.7/site-packages/flask/_compat.py", line 39, in reraise
    raise value
  File "/usr/local/lib/python3.7/site-packages/flask/app.py", line 1949, in full_dispatch_request
    rv = self.dispatch_request()
  File "/usr/local/lib/python3.7/site-packages/flask/app.py", line 1935, in dispatch_request
    return self.view_functions[rule.endpoint](**req.view_args)
  File "/workspace/whaaats_new/chatbot.py", line 18, in Message
    keyword.index(ascending=False)
TypeError: 'Int64Index' object is not callable
172.17.0.1 - - [15/Oct/2020 10:46:21] "[1m[35mPOST /message HTTP/1.1[0m" 500 -
[2020-10-15 10:46:30,639] ERROR in app: Exception on /message [POST]
Traceback (most recent call last):
  File "/usr/local/lib/python3.7/site-packages/flask/app.py", line 2446, in wsgi_app
    response = self.full_dispatch_request()
  File "/usr/local/lib/python3.7/site-packages/flask/app.py", line 1951, in full_dispatch_request
    rv = self.handle_user_exception(e)
  File "/usr/local/lib/python3.7/site-packages/flask/app.py", line 1820, in handle_user_exception
    reraise(exc_type, exc_value, tb)
  File "/usr/local/lib/python3.7/site-packages/flask/_compat.py", line 39, in reraise
    raise value
  File "/usr/local/lib/python3.7/site-packages/flask/app.py", line 1949, in full_dispatch_request
    rv = self.dispatch_request()
  File "/usr/local/lib/python3.7/site-packages/flask/app.py", line 1935, in dispatch_request
    return self.view_functions[rule.endpoint](**req.view_args)
  File "/workspace/whaaats_new/chatbot.py", line 18, in Message
    keyword.index(ascending=False)
TypeError: 'Int64Index' object is not callable
172.17.0.1 - - [15/Oct/2020 10:46:30] "[1m[35mPOST /message HTTP/1.1[0m" 500 -
[2020-10-15 10:46:41,225] ERROR in app: Exception on /message [POST]
Traceback (most recent call last):
  File "/usr/local/lib/python3.7/site-packages/flask/app.py", line 2446, in wsgi_app
    response = self.full_dispatch_request()
  File "/usr/local/lib/python3.7/site-packages/flask/app.py", line 1951, in full_dispatch_request
    rv = self.handle_user_exception(e)
  File "/usr/local/lib/python3.7/site-packages/flask/app.py", line 1820, in handle_user_exception
    reraise(exc_type, exc_value, tb)
  File "/usr/local/lib/python3.7/site-packages/flask/_compat.py", line 39, in reraise
    raise value
  File "/usr/local/lib/python3.7/site-packages/flask/app.py", line 1949, in full_dispatch_request
    rv = self.dispatch_request()
  File "/usr/local/lib/python3.7/site-packages/flask/app.py", line 1935, in dispatch_request
    return self.view_functions[rule.endpoint](**req.view_args)
  File "/workspace/whaaats_new/chatbot.py", line 18, in Message
    keyword.index(ascending=False)
TypeError: 'Int64Index' object is not callable
172.17.0.1 - - [15/Oct/2020 10:46:41] "[1m[35mPOST /message HTTP/1.1[0m" 500 -
[2020-10-15 10:46:51,137] ERROR in app: Exception on /message [POST]
Traceback (most recent call last):
  File "/usr/local/lib/python3.7/site-packages/flask/app.py", line 2446, in wsgi_app
    response = self.full_dispatch_request()
  File "/usr/local/lib/python3.7/site-packages/flask/app.py", line 1951, in full_dispatch_request
    rv = self.handle_user_exception(e)
  File "/usr/local/lib/python3.7/site-packages/flask/app.py", line 1820, in handle_user_exception
    reraise(exc_type, exc_value, tb)
  File "/usr/local/lib/python3.7/site-packages/flask/_compat.py", line 39, in reraise
    raise value
  File "/usr/local/lib/python3.7/site-packages/flask/app.py", line 1949, in full_dispatch_request
    rv = self.dispatch_request()
  File "/usr/local/lib/python3.7/site-packages/flask/app.py", line 1935, in dispatch_request
    return self.view_functions[rule.endpoint](**req.view_args)
  File "/workspace/whaaats_new/chatbot.py", line 18, in Message
    keyword.index(ascending=False)
TypeError: 'Int64Index' object is not callable
172.17.0.1 - - [15/Oct/2020 10:46:51] "[1m[35mPOST /message HTTP/1.1[0m" 500 -
[2020-10-15 10:47:00,890] ERROR in app: Exception on /message [POST]
Traceback (most recent call last):
  File "/usr/local/lib/python3.7/site-packages/flask/app.py", line 2446, in wsgi_app
    response = self.full_dispatch_request()
  File "/usr/local/lib/python3.7/site-packages/flask/app.py", line 1951, in full_dispatch_request
    rv = self.handle_user_exception(e)
  File "/usr/local/lib/python3.7/site-packages/flask/app.py", line 1820, in handle_user_exception
    reraise(exc_type, exc_value, tb)
  File "/usr/local/lib/python3.7/site-packages/flask/_compat.py", line 39, in reraise
    raise value
  File "/usr/local/lib/python3.7/site-packages/flask/app.py", line 1949, in full_dispatch_request
    rv = self.dispatch_request()
  File "/usr/local/lib/python3.7/site-packages/flask/app.py", line 1935, in dispatch_request
    return self.view_functions[rule.endpoint](**req.view_args)
  File "/workspace/whaaats_new/chatbot.py", line 18, in Message
    keyword.index(ascending=False)
TypeError: 'Int64Index' object is not callable
172.17.0.1 - - [15/Oct/2020 10:47:00] "[1m[35mPOST /message HTTP/1.1[0m" 500 -
172.17.0.1 - - [15/Oct/2020 10:47:05] "[37mPOST /message HTTP/1.1[0m" 200 -
[2020-10-15 10:47:59,630] ERROR in app: Exception on /message [POST]
Traceback (most recent call last):
  File "/usr/local/lib/python3.7/site-packages/flask/app.py", line 2446, in wsgi_app
    response = self.full_dispatch_request()
  File "/usr/local/lib/python3.7/site-packages/flask/app.py", line 1951, in full_dispatch_request
    rv = self.handle_user_exception(e)
  File "/usr/local/lib/python3.7/site-packages/flask/app.py", line 1820, in handle_user_exception
    reraise(exc_type, exc_value, tb)
  File "/usr/local/lib/python3.7/site-packages/flask/_compat.py", line 39, in reraise
    raise value
  File "/usr/local/lib/python3.7/site-packages/flask/app.py", line 1949, in full_dispatch_request
    rv = self.dispatch_request()
  File "/usr/local/lib/python3.7/site-packages/flask/app.py", line 1935, in dispatch_request
    return self.view_functions[rule.endpoint](**req.view_args)
  File "/workspace/whaaats_new/chatbot.py", line 18, in Message
    keyword.index(ascending=False)
TypeError: 'Int64Index' object is not callable
172.17.0.1 - - [15/Oct/2020 10:47:59] "[1m[35mPOST /message HTTP/1.1[0m" 500 -
[2020-10-15 10:49:46,207] ERROR in app: Exception on /message [POST]
Traceback (most recent call last):
  File "/usr/local/lib/python3.7/site-packages/flask/app.py", line 2446, in wsgi_app
    response = self.full_dispatch_request()
  File "/usr/local/lib/python3.7/site-packages/flask/app.py", line 1951, in full_dispatch_request
    rv = self.handle_user_exception(e)
  File "/usr/local/lib/python3.7/site-packages/flask/app.py", line 1820, in handle_user_exception
    reraise(exc_type, exc_value, tb)
  File "/usr/local/lib/python3.7/site-packages/flask/_compat.py", line 39, in reraise
    raise value
  File "/usr/local/lib/python3.7/site-packages/flask/app.py", line 1949, in full_dispatch_request
    rv = self.dispatch_request()
  File "/usr/local/lib/python3.7/site-packages/flask/app.py", line 1935, in dispatch_request
    return self.view_functions[rule.endpoint](**req.view_args)
  File "/workspace/whaaats_new/chatbot.py", line 18, in Message
    keyword.index(ascending=False)
TypeError: 'Int64Index' object is not callable
172.17.0.1 - - [15/Oct/2020 10:49:46] "[1m[35mPOST /message HTTP/1.1[0m" 500 -
[2020-10-15 10:50:02,474] ERROR in app: Exception on /message [POST]
Traceback (most recent call last):
  File "/usr/local/lib/python3.7/site-packages/flask/app.py", line 2446, in wsgi_app
    response = self.full_dispatch_request()
  File "/usr/local/lib/python3.7/site-packages/flask/app.py", line 1951, in full_dispatch_request
    rv = self.handle_user_exception(e)
  File "/usr/local/lib/python3.7/site-packages/flask/app.py", line 1820, in handle_user_exception
    reraise(exc_type, exc_value, tb)
  File "/usr/local/lib/python3.7/site-packages/flask/_compat.py", line 39, in reraise
    raise value
  File "/usr/local/lib/python3.7/site-packages/flask/app.py", line 1949, in full_dispatch_request
    rv = self.dispatch_request()
  File "/usr/local/lib/python3.7/site-packages/flask/app.py", line 1935, in dispatch_request
    return self.view_functions[rule.endpoint](**req.view_args)
  File "/workspace/whaaats_new/chatbot.py", line 18, in Message
    keyword.index(ascending=False)
TypeError: 'Int64Index' object is not callable
172.17.0.1 - - [15/Oct/2020 10:50:02] "[1m[35mPOST /message HTTP/1.1[0m" 500 -
[2020-10-15 10:50:13,816] ERROR in app: Exception on /message [POST]
Traceback (most recent call last):
  File "/usr/local/lib/python3.7/site-packages/flask/app.py", line 2446, in wsgi_app
    response = self.full_dispatch_request()
  File "/usr/local/lib/python3.7/site-packages/flask/app.py", line 1951, in full_dispatch_request
    rv = self.handle_user_exception(e)
  File "/usr/local/lib/python3.7/site-packages/flask/app.py", line 1820, in handle_user_exception
    reraise(exc_type, exc_value, tb)
  File "/usr/local/lib/python3.7/site-packages/flask/_compat.py", line 39, in reraise
    raise value
  File "/usr/local/lib/python3.7/site-packages/flask/app.py", line 1949, in full_dispatch_request
    rv = self.dispatch_request()
  File "/usr/local/lib/python3.7/site-packages/flask/app.py", line 1935, in dispatch_request
    return self.view_functions[rule.endpoint](**req.view_args)
  File "/workspace/whaaats_new/chatbot.py", line 18, in Message
    keyword.index(ascending=False)
TypeError: 'Int64Index' object is not callable
172.17.0.1 - - [15/Oct/2020 10:50:13] "[1m[35mPOST /message HTTP/1.1[0m" 500 -
[2020-10-15 10:50:20,261] ERROR in app: Exception on /message [POST]
Traceback (most recent call last):
  File "/usr/local/lib/python3.7/site-packages/flask/app.py", line 2446, in wsgi_app
    response = self.full_dispatch_request()
  File "/usr/local/lib/python3.7/site-packages/flask/app.py", line 1951, in full_dispatch_request
    rv = self.handle_user_exception(e)
  File "/usr/local/lib/python3.7/site-packages/flask/app.py", line 1820, in handle_user_exception
    reraise(exc_type, exc_value, tb)
  File "/usr/local/lib/python3.7/site-packages/flask/_compat.py", line 39, in reraise
    raise value
  File "/usr/local/lib/python3.7/site-packages/flask/app.py", line 1949, in full_dispatch_request
    rv = self.dispatch_request()
  File "/usr/local/lib/python3.7/site-packages/flask/app.py", line 1935, in dispatch_request
    return self.view_functions[rule.endpoint](**req.view_args)
  File "/workspace/whaaats_new/chatbot.py", line 18, in Message
    keyword.index(ascending=False)
TypeError: 'Int64Index' object is not callable
172.17.0.1 - - [15/Oct/2020 10:50:20] "[1m[35mPOST /message HTTP/1.1[0m" 500 -
[2020-10-15 10:50:28,864] ERROR in app: Exception on /message [POST]
Traceback (most recent call last):
  File "/usr/local/lib/python3.7/site-packages/flask/app.py", line 2446, in wsgi_app
    response = self.full_dispatch_request()
  File "/usr/local/lib/python3.7/site-packages/flask/app.py", line 1951, in full_dispatch_request
    rv = self.handle_user_exception(e)
  File "/usr/local/lib/python3.7/site-packages/flask/app.py", line 1820, in handle_user_exception
    reraise(exc_type, exc_value, tb)
  File "/usr/local/lib/python3.7/site-packages/flask/_compat.py", line 39, in reraise
    raise value
  File "/usr/local/lib/python3.7/site-packages/flask/app.py", line 1949, in full_dispatch_request
    rv = self.dispatch_request()
  File "/usr/local/lib/python3.7/site-packages/flask/app.py", line 1935, in dispatch_request
    return self.view_functions[rule.endpoint](**req.view_args)
  File "/workspace/whaaats_new/chatbot.py", line 18, in Message
    keyword.index(ascending=False)
TypeError: 'Int64Index' object is not callable
172.17.0.1 - - [15/Oct/2020 10:50:28] "[1m[35mPOST /message HTTP/1.1[0m" 500 -
[2020-10-15 10:50:31,582] ERROR in app: Exception on /message [POST]
Traceback (most recent call last):
  File "/usr/local/lib/python3.7/site-packages/flask/app.py", line 2446, in wsgi_app
    response = self.full_dispatch_request()
  File "/usr/local/lib/python3.7/site-packages/flask/app.py", line 1951, in full_dispatch_request
    rv = self.handle_user_exception(e)
  File "/usr/local/lib/python3.7/site-packages/flask/app.py", line 1820, in handle_user_exception
    reraise(exc_type, exc_value, tb)
  File "/usr/local/lib/python3.7/site-packages/flask/_compat.py", line 39, in reraise
    raise value
  File "/usr/local/lib/python3.7/site-packages/flask/app.py", line 1949, in full_dispatch_request
    rv = self.dispatch_request()
  File "/usr/local/lib/python3.7/site-packages/flask/app.py", line 1935, in dispatch_request
    return self.view_functions[rule.endpoint](**req.view_args)
  File "/workspace/whaaats_new/chatbot.py", line 18, in Message
    keyword.index(ascending=False)
TypeError: 'Int64Index' object is not callable
172.17.0.1 - - [15/Oct/2020 10:50:31] "[1m[35mPOST /message HTTP/1.1[0m" 500 -
[2020-10-15 10:50:39,357] ERROR in app: Exception on /message [POST]
Traceback (most recent call last):
  File "/usr/local/lib/python3.7/site-packages/flask/app.py", line 2446, in wsgi_app
    response = self.full_dispatch_request()
  File "/usr/local/lib/python3.7/site-packages/flask/app.py", line 1951, in full_dispatch_request
    rv = self.handle_user_exception(e)
  File "/usr/local/lib/python3.7/site-packages/flask/app.py", line 1820, in handle_user_exception
    reraise(exc_type, exc_value, tb)
  File "/usr/local/lib/python3.7/site-packages/flask/_compat.py", line 39, in reraise
    raise value
  File "/usr/local/lib/python3.7/site-packages/flask/app.py", line 1949, in full_dispatch_request
    rv = self.dispatch_request()
  File "/usr/local/lib/python3.7/site-packages/flask/app.py", line 1935, in dispatch_request
    return self.view_functions[rule.endpoint](**req.view_args)
  File "/workspace/whaaats_new/chatbot.py", line 18, in Message
    keyword.index(ascending=False)
TypeError: 'Int64Index' object is not callable
172.17.0.1 - - [15/Oct/2020 10:50:39] "[1m[35mPOST /message HTTP/1.1[0m" 500 -
[2020-10-15 10:50:46,792] ERROR in app: Exception on /message [POST]
Traceback (most recent call last):
  File "/usr/local/lib/python3.7/site-packages/flask/app.py", line 2446, in wsgi_app
    response = self.full_dispatch_request()
  File "/usr/local/lib/python3.7/site-packages/flask/app.py", line 1951, in full_dispatch_request
    rv = self.handle_user_exception(e)
  File "/usr/local/lib/python3.7/site-packages/flask/app.py", line 1820, in handle_user_exception
    reraise(exc_type, exc_value, tb)
  File "/usr/local/lib/python3.7/site-packages/flask/_compat.py", line 39, in reraise
    raise value
  File "/usr/local/lib/python3.7/site-packages/flask/app.py", line 1949, in full_dispatch_request
    rv = self.dispatch_request()
  File "/usr/local/lib/python3.7/site-packages/flask/app.py", line 1935, in dispatch_request
    return self.view_functions[rule.endpoint](**req.view_args)
  File "/workspace/whaaats_new/chatbot.py", line 18, in Message
    keyword.index(ascending=False)
TypeError: 'Int64Index' object is not callable
172.17.0.1 - - [15/Oct/2020 10:50:46] "[1m[35mPOST /message HTTP/1.1[0m" 500 -
172.17.0.1 - - [15/Oct/2020 10:50:52] "[37mPOST /message HTTP/1.1[0m" 200 -
[2020-10-15 10:52:01,834] ERROR in app: Exception on /message [POST]
Traceback (most recent call last):
  File "/usr/local/lib/python3.7/site-packages/flask/app.py", line 2446, in wsgi_app
    response = self.full_dispatch_request()
  File "/usr/local/lib/python3.7/site-packages/flask/app.py", line 1951, in full_dispatch_request
    rv = self.handle_user_exception(e)
  File "/usr/local/lib/python3.7/site-packages/flask/app.py", line 1820, in handle_user_exception
    reraise(exc_type, exc_value, tb)
  File "/usr/local/lib/python3.7/site-packages/flask/_compat.py", line 39, in reraise
    raise value
  File "/usr/local/lib/python3.7/site-packages/flask/app.py", line 1949, in full_dispatch_request
    rv = self.dispatch_request()
  File "/usr/local/lib/python3.7/site-packages/flask/app.py", line 1935, in dispatch_request
    return self.view_functions[rule.endpoint](**req.view_args)
  File "/workspace/whaaats_new/chatbot.py", line 18, in Message
    keyword.index(ascending=False)
TypeError: 'Int64Index' object is not callable
172.17.0.1 - - [15/Oct/2020 10:52:01] "[1m[35mPOST /message HTTP/1.1[0m" 500 -
[2020-10-15 10:54:16,049] ERROR in app: Exception on /message [POST]
Traceback (most recent call last):
  File "/usr/local/lib/python3.7/site-packages/flask/app.py", line 2446, in wsgi_app
    response = self.full_dispatch_request()
  File "/usr/local/lib/python3.7/site-packages/flask/app.py", line 1951, in full_dispatch_request
    rv = self.handle_user_exception(e)
  File "/usr/local/lib/python3.7/site-packages/flask/app.py", line 1820, in handle_user_exception
    reraise(exc_type, exc_value, tb)
  File "/usr/local/lib/python3.7/site-packages/flask/_compat.py", line 39, in reraise
    raise value
  File "/usr/local/lib/python3.7/site-packages/flask/app.py", line 1949, in full_dispatch_request
    rv = self.dispatch_request()
  File "/usr/local/lib/python3.7/site-packages/flask/app.py", line 1935, in dispatch_request
    return self.view_functions[rule.endpoint](**req.view_args)
  File "/workspace/whaaats_new/chatbot.py", line 18, in Message
    keyword.index(ascending=False)
TypeError: 'Int64Index' object is not callable
172.17.0.1 - - [15/Oct/2020 10:54:16] "[1m[35mPOST /message HTTP/1.1[0m" 500 -
[2020-10-15 10:54:19,853] ERROR in app: Exception on /message [POST]
Traceback (most recent call last):
  File "/usr/local/lib/python3.7/site-packages/flask/app.py", line 2446, in wsgi_app
    response = self.full_dispatch_request()
  File "/usr/local/lib/python3.7/site-packages/flask/app.py", line 1951, in full_dispatch_request
    rv = self.handle_user_exception(e)
  File "/usr/local/lib/python3.7/site-packages/flask/app.py", line 1820, in handle_user_exception
    reraise(exc_type, exc_value, tb)
  File "/usr/local/lib/python3.7/site-packages/flask/_compat.py", line 39, in reraise
    raise value
  File "/usr/local/lib/python3.7/site-packages/flask/app.py", line 1949, in full_dispatch_request
    rv = self.dispatch_request()
  File "/usr/local/lib/python3.7/site-packages/flask/app.py", line 1935, in dispatch_request
    return self.view_functions[rule.endpoint](**req.view_args)
  File "/workspace/whaaats_new/chatbot.py", line 18, in Message
    keyword.index(ascending=False)
TypeError: 'Int64Index' object is not callable
172.17.0.1 - - [15/Oct/2020 10:54:19] "[1m[35mPOST /message HTTP/1.1[0m" 500 -
[2020-10-15 10:54:34,586] ERROR in app: Exception on /message [POST]
Traceback (most recent call last):
  File "/usr/local/lib/python3.7/site-packages/flask/app.py", line 2446, in wsgi_app
    response = self.full_dispatch_request()
  File "/usr/local/lib/python3.7/site-packages/flask/app.py", line 1951, in full_dispatch_request
    rv = self.handle_user_exception(e)
  File "/usr/local/lib/python3.7/site-packages/flask/app.py", line 1820, in handle_user_exception
    reraise(exc_type, exc_value, tb)
  File "/usr/local/lib/python3.7/site-packages/flask/_compat.py", line 39, in reraise
    raise value
  File "/usr/local/lib/python3.7/site-packages/flask/app.py", line 1949, in full_dispatch_request
    rv = self.dispatch_request()
  File "/usr/local/lib/python3.7/site-packages/flask/app.py", line 1935, in dispatch_request
    return self.view_functions[rule.endpoint](**req.view_args)
  File "/workspace/whaaats_new/chatbot.py", line 18, in Message
    keyword.index(ascending=False)
TypeError: 'Int64Index' object is not callable
172.17.0.1 - - [15/Oct/2020 10:54:34] "[1m[35mPOST /message HTTP/1.1[0m" 500 -
172.17.0.1 - - [15/Oct/2020 10:55:08] "[37mPOST /message HTTP/1.1[0m" 200 -
172.17.0.1 - - [15/Oct/2020 10:55:15] "[37mPOST /message HTTP/1.1[0m" 200 -
172.17.0.1 - - [15/Oct/2020 10:55:24] "[37mPOST /message HTTP/1.1[0m" 200 -
172.17.0.1 - - [15/Oct/2020 10:55:32] "[37mPOST /message HTTP/1.1[0m" 200 -
172.17.0.1 - - [15/Oct/2020 10:55:39] "[37mPOST /message HTTP/1.1[0m" 200 -
[2020-10-15 10:55:58,477] ERROR in app: Exception on /message [POST]
Traceback (most recent call last):
  File "/usr/local/lib/python3.7/site-packages/flask/app.py", line 2446, in wsgi_app
    response = self.full_dispatch_request()
  File "/usr/local/lib/python3.7/site-packages/flask/app.py", line 1951, in full_dispatch_request
    rv = self.handle_user_exception(e)
  File "/usr/local/lib/python3.7/site-packages/flask/app.py", line 1820, in handle_user_exception
    reraise(exc_type, exc_value, tb)
  File "/usr/local/lib/python3.7/site-packages/flask/_compat.py", line 39, in reraise
    raise value
  File "/usr/local/lib/python3.7/site-packages/flask/app.py", line 1949, in full_dispatch_request
    rv = self.dispatch_request()
  File "/usr/local/lib/python3.7/site-packages/flask/app.py", line 1935, in dispatch_request
    return self.view_functions[rule.endpoint](**req.view_args)
  File "/workspace/whaaats_new/chatbot.py", line 18, in Message
    keyword.index(ascending=False)
TypeError: 'Int64Index' object is not callable
172.17.0.1 - - [15/Oct/2020 10:55:58] "[1m[35mPOST /message HTTP/1.1[0m" 500 -
[2020-10-15 10:56:02,281] ERROR in app: Exception on /message [POST]
Traceback (most recent call last):
  File "/usr/local/lib/python3.7/site-packages/flask/app.py", line 2446, in wsgi_app
    response = self.full_dispatch_request()
  File "/usr/local/lib/python3.7/site-packages/flask/app.py", line 1951, in full_dispatch_request
    rv = self.handle_user_exception(e)
  File "/usr/local/lib/python3.7/site-packages/flask/app.py", line 1820, in handle_user_exception
    reraise(exc_type, exc_value, tb)
  File "/usr/local/lib/python3.7/site-packages/flask/_compat.py", line 39, in reraise
    raise value
  File "/usr/local/lib/python3.7/site-packages/flask/app.py", line 1949, in full_dispatch_request
    rv = self.dispatch_request()
  File "/usr/local/lib/python3.7/site-packages/flask/app.py", line 1935, in dispatch_request
    return self.view_functions[rule.endpoint](**req.view_args)
  File "/workspace/whaaats_new/chatbot.py", line 18, in Message
    keyword.index(ascending=False)
TypeError: 'Int64Index' object is not callable
172.17.0.1 - - [15/Oct/2020 10:56:02] "[1m[35mPOST /message HTTP/1.1[0m" 500 -
172.17.0.1 - - [15/Oct/2020 10:56:43] "[37mPOST /message HTTP/1.1[0m" 200 -
[2020-10-15 11:01:25,114] ERROR in app: Exception on /message [POST]
Traceback (most recent call last):
  File "/usr/local/lib/python3.7/site-packages/flask/app.py", line 2446, in wsgi_app
    response = self.full_dispatch_request()
  File "/usr/local/lib/python3.7/site-packages/flask/app.py", line 1951, in full_dispatch_request
    rv = self.handle_user_exception(e)
  File "/usr/local/lib/python3.7/site-packages/flask/app.py", line 1820, in handle_user_exception
    reraise(exc_type, exc_value, tb)
  File "/usr/local/lib/python3.7/site-packages/flask/_compat.py", line 39, in reraise
    raise value
  File "/usr/local/lib/python3.7/site-packages/flask/app.py", line 1949, in full_dispatch_request
    rv = self.dispatch_request()
  File "/usr/local/lib/python3.7/site-packages/flask/app.py", line 1935, in dispatch_request
    return self.view_functions[rule.endpoint](**req.view_args)
  File "/workspace/whaaats_new/chatbot.py", line 18, in Message
    # keyword.index(ascending=False)
TypeError: 'Int64Index' object is not callable
172.17.0.1 - - [15/Oct/2020 11:01:25] "[1m[35mPOST /message HTTP/1.1[0m" 500 -
[2020-10-15 11:01:29,305] ERROR in app: Exception on /message [POST]
Traceback (most recent call last):
  File "/usr/local/lib/python3.7/site-packages/flask/app.py", line 2446, in wsgi_app
    response = self.full_dispatch_request()
  File "/usr/local/lib/python3.7/site-packages/flask/app.py", line 1951, in full_dispatch_request
    rv = self.handle_user_exception(e)
  File "/usr/local/lib/python3.7/site-packages/flask/app.py", line 1820, in handle_user_exception
    reraise(exc_type, exc_value, tb)
  File "/usr/local/lib/python3.7/site-packages/flask/_compat.py", line 39, in reraise
    raise value
  File "/usr/local/lib/python3.7/site-packages/flask/app.py", line 1949, in full_dispatch_request
    rv = self.dispatch_request()
  File "/usr/local/lib/python3.7/site-packages/flask/app.py", line 1935, in dispatch_request
    return self.view_functions[rule.endpoint](**req.view_args)
  File "/workspace/whaaats_new/chatbot.py", line 18, in Message
    # keyword.index(ascending=False)
TypeError: 'Int64Index' object is not callable
172.17.0.1 - - [15/Oct/2020 11:01:29] "[1m[35mPOST /message HTTP/1.1[0m" 500 -
 * Serving Flask app "chatbot" (lazy loading)
 * Environment: production
   WARNING: This is a development server. Do not use it in a production deployment.
   Use a production WSGI server instead.
 * Debug mode: off
Traceback (most recent call last):
  File "/workspace/whaaats_new/chatbot.py", line 101, in <module>
    app.run(host='0.0.0.0')
  File "/usr/local/lib/python3.7/site-packages/flask/app.py", line 990, in run
    run_simple(host, port, self, **options)
  File "/usr/local/lib/python3.7/site-packages/werkzeug/serving.py", line 1010, in run_simple
    inner()
  File "/usr/local/lib/python3.7/site-packages/werkzeug/serving.py", line 963, in inner
    fd=fd,
  File "/usr/local/lib/python3.7/site-packages/werkzeug/serving.py", line 806, in make_server
    host, port, app, request_handler, passthrough_errors, ssl_context, fd=fd
  File "/usr/local/lib/python3.7/site-packages/werkzeug/serving.py", line 699, in __init__
    HTTPServer.__init__(self, server_address, handler)
  File "/usr/local/lib/python3.7/socketserver.py", line 452, in __init__
    self.server_bind()
  File "/usr/local/lib/python3.7/http/server.py", line 137, in server_bind
    socketserver.TCPServer.server_bind(self)
  File "/usr/local/lib/python3.7/socketserver.py", line 466, in server_bind
    self.socket.bind(self.server_address)
OSError: [Errno 98] Address already in use
[2020-10-15 11:03:50,501] ERROR in app: Exception on /message [POST]
Traceback (most recent call last):
  File "/usr/local/lib/python3.7/site-packages/flask/app.py", line 2446, in wsgi_app
    response = self.full_dispatch_request()
  File "/usr/local/lib/python3.7/site-packages/flask/app.py", line 1951, in full_dispatch_request
    rv = self.handle_user_exception(e)
  File "/usr/local/lib/python3.7/site-packages/flask/app.py", line 1820, in handle_user_exception
    reraise(exc_type, exc_value, tb)
  File "/usr/local/lib/python3.7/site-packages/flask/_compat.py", line 39, in reraise
    raise value
  File "/usr/local/lib/python3.7/site-packages/flask/app.py", line 1949, in full_dispatch_request
    rv = self.dispatch_request()
  File "/usr/local/lib/python3.7/site-packages/flask/app.py", line 1935, in dispatch_request
    return self.view_functions[rule.endpoint](**req.view_args)
  File "/workspace/whaaats_new/chatbot.py", line 18, in Message
    # keyword.index(ascending=False)
TypeError: 'Int64Index' object is not callable
172.17.0.1 - - [15/Oct/2020 11:03:50] "[1m[35mPOST /message HTTP/1.1[0m" 500 -
[2020-10-15 11:04:32,588] ERROR in app: Exception on /message [POST]
Traceback (most recent call last):
  File "/usr/local/lib/python3.7/site-packages/flask/app.py", line 2446, in wsgi_app
    response = self.full_dispatch_request()
  File "/usr/local/lib/python3.7/site-packages/flask/app.py", line 1951, in full_dispatch_request
    rv = self.handle_user_exception(e)
  File "/usr/local/lib/python3.7/site-packages/flask/app.py", line 1820, in handle_user_exception
    reraise(exc_type, exc_value, tb)
  File "/usr/local/lib/python3.7/site-packages/flask/_compat.py", line 39, in reraise
    raise value
  File "/usr/local/lib/python3.7/site-packages/flask/app.py", line 1949, in full_dispatch_request
    rv = self.dispatch_request()
  File "/usr/local/lib/python3.7/site-packages/flask/app.py", line 1935, in dispatch_request
    return self.view_functions[rule.endpoint](**req.view_args)
  File "/workspace/whaaats_new/chatbot.py", line 18, in Message
    keyword.reset_index(drop=True, inplace=True)
TypeError: 'Int64Index' object is not callable
172.17.0.1 - - [15/Oct/2020 11:04:32] "[1m[35mPOST /message HTTP/1.1[0m" 500 -
172.17.0.1 - - [15/Oct/2020 11:08:32] "[37mPOST /message HTTP/1.1[0m" 200 -
172.17.0.1 - - [15/Oct/2020 11:08:35] "[37mPOST /message HTTP/1.1[0m" 200 -
172.17.0.1 - - [15/Oct/2020 11:08:39] "[37mPOST /message HTTP/1.1[0m" 200 -
172.17.0.1 - - [15/Oct/2020 11:08:54] "[37mPOST /message HTTP/1.1[0m" 200 -
172.17.0.1 - - [15/Oct/2020 11:09:02] "[37mPOST /message HTTP/1.1[0m" 200 -
172.17.0.1 - - [15/Oct/2020 11:09:06] "[37mPOST /message HTTP/1.1[0m" 200 -
172.17.0.1 - - [15/Oct/2020 11:09:14] "[37mPOST /message HTTP/1.1[0m" 200 -
[2020-10-15 11:09:20,355] ERROR in app: Exception on /message [POST]
Traceback (most recent call last):
  File "/usr/local/lib/python3.7/site-packages/flask/app.py", line 2446, in wsgi_app
    response = self.full_dispatch_request()
  File "/usr/local/lib/python3.7/site-packages/flask/app.py", line 1951, in full_dispatch_request
    rv = self.handle_user_exception(e)
  File "/usr/local/lib/python3.7/site-packages/flask/app.py", line 1820, in handle_user_exception
    reraise(exc_type, exc_value, tb)
  File "/usr/local/lib/python3.7/site-packages/flask/_compat.py", line 39, in reraise
    raise value
  File "/usr/local/lib/python3.7/site-packages/flask/app.py", line 1949, in full_dispatch_request
    rv = self.dispatch_request()
  File "/usr/local/lib/python3.7/site-packages/flask/app.py", line 1935, in dispatch_request
    return self.view_functions[rule.endpoint](**req.view_args)
  File "/workspace/whaaats_new/chatbot.py", line 18, in Message
    keyword.reset_index(drop=True, inplace=True)
TypeError: 'Int64Index' object is not callable
172.17.0.1 - - [15/Oct/2020 11:09:20] "[1m[35mPOST /message HTTP/1.1[0m" 500 -
[2020-10-15 11:12:35,401] ERROR in app: Exception on /message [POST]
Traceback (most recent call last):
  File "/usr/local/lib/python3.7/site-packages/flask/app.py", line 2446, in wsgi_app
    response = self.full_dispatch_request()
  File "/usr/local/lib/python3.7/site-packages/flask/app.py", line 1951, in full_dispatch_request
    rv = self.handle_user_exception(e)
  File "/usr/local/lib/python3.7/site-packages/flask/app.py", line 1820, in handle_user_exception
    reraise(exc_type, exc_value, tb)
  File "/usr/local/lib/python3.7/site-packages/flask/_compat.py", line 39, in reraise
    raise value
  File "/usr/local/lib/python3.7/site-packages/flask/app.py", line 1949, in full_dispatch_request
    rv = self.dispatch_request()
  File "/usr/local/lib/python3.7/site-packages/flask/app.py", line 1935, in dispatch_request
    return self.view_functions[rule.endpoint](**req.view_args)
  File "/workspace/whaaats_new/chatbot.py", line 18, in Message
    keyword.reset_index(drop=True, inplace=True)
TypeError: 'Int64Index' object is not callable
172.17.0.1 - - [15/Oct/2020 11:12:35] "[1m[35mPOST /message HTTP/1.1[0m" 500 -
[2020-10-15 11:16:00,462] ERROR in app: Exception on /message [POST]
Traceback (most recent call last):
  File "/usr/local/lib/python3.7/site-packages/flask/app.py", line 2446, in wsgi_app
    response = self.full_dispatch_request()
  File "/usr/local/lib/python3.7/site-packages/flask/app.py", line 1951, in full_dispatch_request
    rv = self.handle_user_exception(e)
  File "/usr/local/lib/python3.7/site-packages/flask/app.py", line 1820, in handle_user_exception
    reraise(exc_type, exc_value, tb)
  File "/usr/local/lib/python3.7/site-packages/flask/_compat.py", line 39, in reraise
    raise value
  File "/usr/local/lib/python3.7/site-packages/flask/app.py", line 1949, in full_dispatch_request
    rv = self.dispatch_request()
  File "/usr/local/lib/python3.7/site-packages/flask/app.py", line 1935, in dispatch_request
    return self.view_functions[rule.endpoint](**req.view_args)
  File "/workspace/whaaats_new/chatbot.py", line 18, in Message
    keyword.reset_index(drop=True, inplace=True)
TypeError: 'Int64Index' object is not callable
172.17.0.1 - - [15/Oct/2020 11:16:00] "[1m[35mPOST /message HTTP/1.1[0m" 500 -
[2020-10-15 11:16:07,354] ERROR in app: Exception on /message [POST]
Traceback (most recent call last):
  File "/usr/local/lib/python3.7/site-packages/flask/app.py", line 2446, in wsgi_app
    response = self.full_dispatch_request()
  File "/usr/local/lib/python3.7/site-packages/flask/app.py", line 1951, in full_dispatch_request
    rv = self.handle_user_exception(e)
  File "/usr/local/lib/python3.7/site-packages/flask/app.py", line 1820, in handle_user_exception
    reraise(exc_type, exc_value, tb)
  File "/usr/local/lib/python3.7/site-packages/flask/_compat.py", line 39, in reraise
    raise value
  File "/usr/local/lib/python3.7/site-packages/flask/app.py", line 1949, in full_dispatch_request
    rv = self.dispatch_request()
  File "/usr/local/lib/python3.7/site-packages/flask/app.py", line 1935, in dispatch_request
    return self.view_functions[rule.endpoint](**req.view_args)
  File "/workspace/whaaats_new/chatbot.py", line 18, in Message
    keyword.reset_index(drop=True, inplace=True)
TypeError: 'Int64Index' object is not callable
172.17.0.1 - - [15/Oct/2020 11:16:07] "[1m[35mPOST /message HTTP/1.1[0m" 500 -
172.17.0.1 - - [15/Oct/2020 11:16:29] "[37mPOST /message HTTP/1.1[0m" 200 -
172.17.0.1 - - [15/Oct/2020 11:18:14] "[37mPOST /message HTTP/1.1[0m" 200 -
[2020-10-15 11:18:29,019] ERROR in app: Exception on /message [POST]
Traceback (most recent call last):
  File "/usr/local/lib/python3.7/site-packages/flask/app.py", line 2446, in wsgi_app
    response = self.full_dispatch_request()
  File "/usr/local/lib/python3.7/site-packages/flask/app.py", line 1951, in full_dispatch_request
    rv = self.handle_user_exception(e)
  File "/usr/local/lib/python3.7/site-packages/flask/app.py", line 1820, in handle_user_exception
    reraise(exc_type, exc_value, tb)
  File "/usr/local/lib/python3.7/site-packages/flask/_compat.py", line 39, in reraise
    raise value
  File "/usr/local/lib/python3.7/site-packages/flask/app.py", line 1949, in full_dispatch_request
    rv = self.dispatch_request()
  File "/usr/local/lib/python3.7/site-packages/flask/app.py", line 1935, in dispatch_request
    return self.view_functions[rule.endpoint](**req.view_args)
  File "/workspace/whaaats_new/chatbot.py", line 18, in Message
    keyword.reset_index(drop=True, inplace=True)
TypeError: 'Int64Index' object is not callable
172.17.0.1 - - [15/Oct/2020 11:18:29] "[1m[35mPOST /message HTTP/1.1[0m" 500 -
[2020-10-15 11:26:15,166] ERROR in app: Exception on /message [POST]
Traceback (most recent call last):
  File "/usr/local/lib/python3.7/site-packages/flask/app.py", line 2446, in wsgi_app
    response = self.full_dispatch_request()
  File "/usr/local/lib/python3.7/site-packages/flask/app.py", line 1951, in full_dispatch_request
    rv = self.handle_user_exception(e)
  File "/usr/local/lib/python3.7/site-packages/flask/app.py", line 1820, in handle_user_exception
    reraise(exc_type, exc_value, tb)
  File "/usr/local/lib/python3.7/site-packages/flask/_compat.py", line 39, in reraise
    raise value
  File "/usr/local/lib/python3.7/site-packages/flask/app.py", line 1949, in full_dispatch_request
    rv = self.dispatch_request()
  File "/usr/local/lib/python3.7/site-packages/flask/app.py", line 1935, in dispatch_request
    return self.view_functions[rule.endpoint](**req.view_args)
  File "/workspace/whaaats_new/chatbot.py", line 18, in Message
    keyword.reset_index(drop=True, inplace=True)
TypeError: 'Int64Index' object is not callable
172.17.0.1 - - [15/Oct/2020 11:26:15] "[1m[35mPOST /message HTTP/1.1[0m" 500 -
 * Serving Flask app "chatbot" (lazy loading)
 * Environment: production
   WARNING: This is a development server. Do not use it in a production deployment.
   Use a production WSGI server instead.
 * Debug mode: off
 * Running on http://0.0.0.0:5000/ (Press CTRL+C to quit)
172.17.0.1 - - [15/Oct/2020 11:31:30] "[37mPOST /message HTTP/1.1[0m" 200 -
172.17.0.1 - - [15/Oct/2020 11:31:34] "[37mPOST /message HTTP/1.1[0m" 200 -
172.17.0.1 - - [15/Oct/2020 11:32:34] "[37mPOST /message HTTP/1.1[0m" 200 -
172.17.0.1 - - [15/Oct/2020 14:37:00] "[37mPOST /message HTTP/1.1[0m" 200 -
172.17.0.1 - - [15/Oct/2020 14:37:48] "[37mPOST /message HTTP/1.1[0m" 200 -
172.17.0.1 - - [15/Oct/2020 14:37:59] "[37mPOST /message HTTP/1.1[0m" 200 -
172.17.0.1 - - [20/Oct/2020 23:47:57] "[37mPOST /message HTTP/1.1[0m" 200 -
172.17.0.1 - - [23/Oct/2020 03:18:05] "[37mPOST /message HTTP/1.1[0m" 200 -
172.17.0.1 - - [23/Oct/2020 03:19:58] "[37mPOST /message HTTP/1.1[0m" 200 -
172.17.0.1 - - [03/Nov/2020 14:46:47] "[37mPOST /message HTTP/1.1[0m" 200 -
172.17.0.1 - - [03/Nov/2020 14:46:55] "[37mPOST /message HTTP/1.1[0m" 200 -
172.17.0.1 - - [03/Nov/2020 15:17:23] "[37mPOST /message HTTP/1.1[0m" 200 -
172.17.0.1 - - [03/Nov/2020 15:18:04] "[37mPOST /message HTTP/1.1[0m" 200 -
172.17.0.1 - - [03/Nov/2020 15:26:13] "[37mPOST /message HTTP/1.1[0m" 200 -
172.17.0.1 - - [08/Nov/2020 14:23:47] "[37mPOST /message HTTP/1.1[0m" 200 -
172.17.0.1 - - [08/Nov/2020 14:27:05] "[37mPOST /message HTTP/1.1[0m" 200 -
172.17.0.1 - - [08/Nov/2020 14:29:13] "[37mPOST /message HTTP/1.1[0m" 200 -
172.17.0.1 - - [08/Nov/2020 14:34:05] "[37mPOST /message HTTP/1.1[0m" 200 -
172.17.0.1 - - [08/Nov/2020 14:50:44] "[37mPOST /message HTTP/1.1[0m" 200 -
172.17.0.1 - - [09/Nov/2020 05:52:37] "[37mPOST /message HTTP/1.1[0m" 200 -
172.17.0.1 - - [09/Nov/2020 05:52:51] "[37mPOST /message HTTP/1.1[0m" 200 -
172.17.0.1 - - [09/Nov/2020 07:58:18] "[37mPOST /message HTTP/1.1[0m" 200 -
172.17.0.1 - - [09/Nov/2020 07:58:46] "[37mPOST /message HTTP/1.1[0m" 200 -
172.17.0.1 - - [09/Nov/2020 07:59:08] "[37mPOST /message HTTP/1.1[0m" 200 -
172.17.0.1 - - [09/Nov/2020 21:25:24] "[37mPOST /message HTTP/1.1[0m" 200 -
172.17.0.1 - - [17/Nov/2020 11:00:17] "[37mPOST /message HTTP/1.1[0m" 200 -
172.17.0.1 - - [17/Nov/2020 12:57:39] "[37mPOST /message HTTP/1.1[0m" 200 -
172.17.0.1 - - [17/Nov/2020 13:04:46] "[37mPOST /message HTTP/1.1[0m" 200 -
172.17.0.1 - - [17/Nov/2020 13:05:05] "[37mPOST /message HTTP/1.1[0m" 200 -
172.17.0.1 - - [17/Nov/2020 13:07:34] "[37mPOST /message HTTP/1.1[0m" 200 -
172.17.0.1 - - [17/Nov/2020 13:09:30] "[37mPOST /message HTTP/1.1[0m" 200 -
172.17.0.1 - - [17/Nov/2020 13:11:08] "[37mPOST /message HTTP/1.1[0m" 200 -
172.17.0.1 - - [17/Nov/2020 14:27:50] "[37mPOST /message HTTP/1.1[0m" 200 -
172.17.0.1 - - [18/Nov/2020 13:58:02] "[37mPOST /message HTTP/1.1[0m" 200 -
172.17.0.1 - - [18/Nov/2020 13:58:27] "[37mPOST /message HTTP/1.1[0m" 200 -
172.17.0.1 - - [20/Nov/2020 05:07:09] "[37mPOST /message HTTP/1.1[0m" 200 -
172.17.0.1 - - [20/Nov/2020 08:25:53] "[37mPOST /message HTTP/1.1[0m" 200 -
172.17.0.1 - - [23/Nov/2020 10:25:00] "[37mPOST /message HTTP/1.1[0m" 200 -
172.17.0.1 - - [23/Nov/2020 10:25:03] "[37mPOST /message HTTP/1.1[0m" 200 -
172.17.0.1 - - [23/Nov/2020 10:25:13] "[37mPOST /message HTTP/1.1[0m" 200 -
172.17.0.1 - - [23/Nov/2020 10:25:20] "[37mPOST /message HTTP/1.1[0m" 200 -
172.17.0.1 - - [28/Nov/2020 00:11:21] "[37mPOST /message HTTP/1.1[0m" 200 -
172.17.0.1 - - [04/Dec/2020 17:51:06] "[37mPOST /message HTTP/1.1[0m" 200 -
172.17.0.1 - - [11/Dec/2020 16:26:58] "[37mPOST /message HTTP/1.1[0m" 200 -
172.17.0.1 - - [11/Dec/2020 16:27:07] "[37mPOST /message HTTP/1.1[0m" 200 -
 * Serving Flask app "chatbot" (lazy loading)
 * Environment: production
   WARNING: This is a development server. Do not use it in a production deployment.
   Use a production WSGI server instead.
 * Debug mode: off
 * Running on http://0.0.0.0:5000/ (Press CTRL+C to quit)
172.17.0.1 - - [28/Dec/2020 16:50:13] "[37mPOST /message HTTP/1.1[0m" 200 -
[2020-12-28 17:05:24,777] ERROR in app: Exception on /message [POST]
Traceback (most recent call last):
  File "/usr/local/lib/python3.7/site-packages/flask/app.py", line 2447, in wsgi_app
    response = self.full_dispatch_request()
  File "/usr/local/lib/python3.7/site-packages/flask/app.py", line 1952, in full_dispatch_request
    rv = self.handle_user_exception(e)
  File "/usr/local/lib/python3.7/site-packages/flask/app.py", line 1821, in handle_user_exception
    reraise(exc_type, exc_value, tb)
  File "/usr/local/lib/python3.7/site-packages/flask/_compat.py", line 39, in reraise
    raise value
  File "/usr/local/lib/python3.7/site-packages/flask/app.py", line 1950, in full_dispatch_request
    rv = self.dispatch_request()
  File "/usr/local/lib/python3.7/site-packages/flask/app.py", line 1936, in dispatch_request
    return self.view_functions[rule.endpoint](**req.view_args)
  File "/workspace/whaaats_new/chatbot.py", line 95, in Message
    return jsonify(dataSend)
UnboundLocalError: local variable 'dataSend' referenced before assignment
172.17.0.1 - - [28/Dec/2020 17:05:24] "[35m[1mPOST /message HTTP/1.1[0m" 500 -
[2020-12-28 17:05:32,791] ERROR in app: Exception on /message [POST]
Traceback (most recent call last):
  File "/usr/local/lib/python3.7/site-packages/flask/app.py", line 2447, in wsgi_app
    response = self.full_dispatch_request()
  File "/usr/local/lib/python3.7/site-packages/flask/app.py", line 1952, in full_dispatch_request
    rv = self.handle_user_exception(e)
  File "/usr/local/lib/python3.7/site-packages/flask/app.py", line 1821, in handle_user_exception
    reraise(exc_type, exc_value, tb)
  File "/usr/local/lib/python3.7/site-packages/flask/_compat.py", line 39, in reraise
    raise value
  File "/usr/local/lib/python3.7/site-packages/flask/app.py", line 1950, in full_dispatch_request
    rv = self.dispatch_request()
  File "/usr/local/lib/python3.7/site-packages/flask/app.py", line 1936, in dispatch_request
    return self.view_functions[rule.endpoint](**req.view_args)
  File "/workspace/whaaats_new/chatbot.py", line 95, in Message
    return jsonify(dataSend)
UnboundLocalError: local variable 'dataSend' referenced before assignment
172.17.0.1 - - [28/Dec/2020 17:05:32] "[35m[1mPOST /message HTTP/1.1[0m" 500 -
172.17.0.1 - - [28/Dec/2020 17:05:43] "[37mPOST /message HTTP/1.1[0m" 200 -
172.17.0.1 - - [28/Dec/2020 18:14:36] "[37mPOST /message HTTP/1.1[0m" 200 -
172.17.0.1 - - [28/Dec/2020 18:14:41] "[37mPOST /message HTTP/1.1[0m" 200 -
172.17.0.1 - - [28/Dec/2020 18:14:46] "[37mPOST /message HTTP/1.1[0m" 200 -
172.17.0.1 - - [28/Dec/2020 18:14:51] "[37mPOST /message HTTP/1.1[0m" 200 -
172.17.0.1 - - [28/Dec/2020 18:15:02] "[37mPOST /message HTTP/1.1[0m" 200 -
172.17.0.1 - - [28/Dec/2020 18:15:10] "[37mPOST /message HTTP/1.1[0m" 200 -
172.17.0.1 - - [28/Dec/2020 18:15:24] "[37mPOST /message HTTP/1.1[0m" 200 -
172.17.0.1 - - [28/Dec/2020 18:16:34] "[37mPOST /message HTTP/1.1[0m" 200 -
172.17.0.1 - - [07/Jan/2021 13:49:59] "[37mPOST /message HTTP/1.1[0m" 200 -
194.61.54.115 - - [08/Jan/2021 00:38:28] code 400, message Bad HTTP/0.9 request type ('\x03\x00\x00/*à\x00\x00\x00\x00\x00Cookie:')
194.61.54.115 - - [08/Jan/2021 00:38:28] "[35m[1m  /*à     Cookie: mstshash=Administr[0m" HTTPStatus.BAD_REQUEST -
194.61.54.115 - - [08/Jan/2021 00:38:28] code 400, message Bad HTTP/0.9 request type ('\x03\x00\x00/*à\x00\x00\x00\x00\x00Cookie:')
194.61.54.115 - - [08/Jan/2021 00:38:28] "[35m[1m  /*à     Cookie: mstshash=Administr[0m" HTTPStatus.BAD_REQUEST -
172.17.0.1 - - [08/Jan/2021 09:30:05] "[37mPOST /message HTTP/1.1[0m" 200 -
172.17.0.1 - - [08/Jan/2021 11:39:44] "[37mPOST /message HTTP/1.1[0m" 200 -
172.17.0.1 - - [08/Jan/2021 11:40:19] "[37mPOST /message HTTP/1.1[0m" 200 -
172.17.0.1 - - [08/Jan/2021 11:40:55] "[37mPOST /message HTTP/1.1[0m" 200 -
172.17.0.1 - - [11/Jan/2021 03:20:30] "[37mPOST /message HTTP/1.1[0m" 200 -
172.17.0.1 - - [12/Jan/2021 06:42:54] "[37mPOST /message HTTP/1.1[0m" 200 -
172.17.0.1 - - [12/Jan/2021 06:43:33] "[37mPOST /message HTTP/1.1[0m" 200 -
172.17.0.1 - - [16/Jan/2021 10:09:42] "[37mPOST /message HTTP/1.1[0m" 200 -
[2021-01-16 10:24:47,728] ERROR in app: Exception on /message [POST]
Traceback (most recent call last):
  File "/usr/local/lib/python3.7/site-packages/flask/app.py", line 2447, in wsgi_app
    response = self.full_dispatch_request()
  File "/usr/local/lib/python3.7/site-packages/flask/app.py", line 1952, in full_dispatch_request
    rv = self.handle_user_exception(e)
  File "/usr/local/lib/python3.7/site-packages/flask/app.py", line 1821, in handle_user_exception
    reraise(exc_type, exc_value, tb)
  File "/usr/local/lib/python3.7/site-packages/flask/_compat.py", line 39, in reraise
    raise value
  File "/usr/local/lib/python3.7/site-packages/flask/app.py", line 1950, in full_dispatch_request
    rv = self.dispatch_request()
  File "/usr/local/lib/python3.7/site-packages/flask/app.py", line 1936, in dispatch_request
    return self.view_functions[rule.endpoint](**req.view_args)
  File "/workspace/whaaats_new/chatbot.py", line 95, in Message
    dataSend = {
UnboundLocalError: local variable 'dataSend' referenced before assignment
172.17.0.1 - - [16/Jan/2021 10:24:47] "[35m[1mPOST /message HTTP/1.1[0m" 500 -
[2021-01-16 10:25:06,844] ERROR in app: Exception on /message [POST]
Traceback (most recent call last):
  File "/usr/local/lib/python3.7/site-packages/flask/app.py", line 2447, in wsgi_app
    response = self.full_dispatch_request()
  File "/usr/local/lib/python3.7/site-packages/flask/app.py", line 1952, in full_dispatch_request
    rv = self.handle_user_exception(e)
  File "/usr/local/lib/python3.7/site-packages/flask/app.py", line 1821, in handle_user_exception
    reraise(exc_type, exc_value, tb)
  File "/usr/local/lib/python3.7/site-packages/flask/_compat.py", line 39, in reraise
    raise value
  File "/usr/local/lib/python3.7/site-packages/flask/app.py", line 1950, in full_dispatch_request
    rv = self.dispatch_request()
  File "/usr/local/lib/python3.7/site-packages/flask/app.py", line 1936, in dispatch_request
    return self.view_functions[rule.endpoint](**req.view_args)
  File "/workspace/whaaats_new/chatbot.py", line 95, in Message
    dataSend = {
UnboundLocalError: local variable 'dataSend' referenced before assignment
172.17.0.1 - - [16/Jan/2021 10:25:06] "[35m[1mPOST /message HTTP/1.1[0m" 500 -
[2021-01-16 10:25:14,122] ERROR in app: Exception on /message [POST]
Traceback (most recent call last):
  File "/usr/local/lib/python3.7/site-packages/flask/app.py", line 2447, in wsgi_app
    response = self.full_dispatch_request()
  File "/usr/local/lib/python3.7/site-packages/flask/app.py", line 1952, in full_dispatch_request
    rv = self.handle_user_exception(e)
  File "/usr/local/lib/python3.7/site-packages/flask/app.py", line 1821, in handle_user_exception
    reraise(exc_type, exc_value, tb)
  File "/usr/local/lib/python3.7/site-packages/flask/_compat.py", line 39, in reraise
    raise value
  File "/usr/local/lib/python3.7/site-packages/flask/app.py", line 1950, in full_dispatch_request
    rv = self.dispatch_request()
  File "/usr/local/lib/python3.7/site-packages/flask/app.py", line 1936, in dispatch_request
    return self.view_functions[rule.endpoint](**req.view_args)
  File "/workspace/whaaats_new/chatbot.py", line 95, in Message
    dataSend = {
UnboundLocalError: local variable 'dataSend' referenced before assignment
172.17.0.1 - - [16/Jan/2021 10:25:14] "[35m[1mPOST /message HTTP/1.1[0m" 500 -
[2021-01-16 10:27:52,019] ERROR in app: Exception on /message [POST]
Traceback (most recent call last):
  File "/usr/local/lib/python3.7/site-packages/flask/app.py", line 2447, in wsgi_app
    response = self.full_dispatch_request()
  File "/usr/local/lib/python3.7/site-packages/flask/app.py", line 1952, in full_dispatch_request
    rv = self.handle_user_exception(e)
  File "/usr/local/lib/python3.7/site-packages/flask/app.py", line 1821, in handle_user_exception
    reraise(exc_type, exc_value, tb)
  File "/usr/local/lib/python3.7/site-packages/flask/_compat.py", line 39, in reraise
    raise value
  File "/usr/local/lib/python3.7/site-packages/flask/app.py", line 1950, in full_dispatch_request
    rv = self.dispatch_request()
  File "/usr/local/lib/python3.7/site-packages/flask/app.py", line 1936, in dispatch_request
    return self.view_functions[rule.endpoint](**req.view_args)
  File "/workspace/whaaats_new/chatbot.py", line 95, in Message
    dataSend = {
UnboundLocalError: local variable 'dataSend' referenced before assignment
172.17.0.1 - - [16/Jan/2021 10:27:52] "[35m[1mPOST /message HTTP/1.1[0m" 500 -
[2021-01-16 10:29:29,174] ERROR in app: Exception on /message [POST]
Traceback (most recent call last):
  File "/usr/local/lib/python3.7/site-packages/flask/app.py", line 2447, in wsgi_app
    response = self.full_dispatch_request()
  File "/usr/local/lib/python3.7/site-packages/flask/app.py", line 1952, in full_dispatch_request
    rv = self.handle_user_exception(e)
  File "/usr/local/lib/python3.7/site-packages/flask/app.py", line 1821, in handle_user_exception
    reraise(exc_type, exc_value, tb)
  File "/usr/local/lib/python3.7/site-packages/flask/_compat.py", line 39, in reraise
    raise value
  File "/usr/local/lib/python3.7/site-packages/flask/app.py", line 1950, in full_dispatch_request
    rv = self.dispatch_request()
  File "/usr/local/lib/python3.7/site-packages/flask/app.py", line 1936, in dispatch_request
    return self.view_functions[rule.endpoint](**req.view_args)
  File "/workspace/whaaats_new/chatbot.py", line 95, in Message
    dataSend = {
UnboundLocalError: local variable 'dataSend' referenced before assignment
172.17.0.1 - - [16/Jan/2021 10:29:29] "[35m[1mPOST /message HTTP/1.1[0m" 500 -
[2021-01-16 10:30:20,312] ERROR in app: Exception on /message [POST]
Traceback (most recent call last):
  File "/usr/local/lib/python3.7/site-packages/flask/app.py", line 2447, in wsgi_app
    response = self.full_dispatch_request()
  File "/usr/local/lib/python3.7/site-packages/flask/app.py", line 1952, in full_dispatch_request
    rv = self.handle_user_exception(e)
  File "/usr/local/lib/python3.7/site-packages/flask/app.py", line 1821, in handle_user_exception
    reraise(exc_type, exc_value, tb)
  File "/usr/local/lib/python3.7/site-packages/flask/_compat.py", line 39, in reraise
    raise value
  File "/usr/local/lib/python3.7/site-packages/flask/app.py", line 1950, in full_dispatch_request
    rv = self.dispatch_request()
  File "/usr/local/lib/python3.7/site-packages/flask/app.py", line 1936, in dispatch_request
    return self.view_functions[rule.endpoint](**req.view_args)
  File "/workspace/whaaats_new/chatbot.py", line 95, in Message
    dataSend = {
UnboundLocalError: local variable 'dataSend' referenced before assignment
172.17.0.1 - - [16/Jan/2021 10:30:20] "[35m[1mPOST /message HTTP/1.1[0m" 500 -
[2021-01-16 10:30:23,941] ERROR in app: Exception on /message [POST]
Traceback (most recent call last):
  File "/usr/local/lib/python3.7/site-packages/flask/app.py", line 2447, in wsgi_app
    response = self.full_dispatch_request()
  File "/usr/local/lib/python3.7/site-packages/flask/app.py", line 1952, in full_dispatch_request
    rv = self.handle_user_exception(e)
  File "/usr/local/lib/python3.7/site-packages/flask/app.py", line 1821, in handle_user_exception
    reraise(exc_type, exc_value, tb)
  File "/usr/local/lib/python3.7/site-packages/flask/_compat.py", line 39, in reraise
    raise value
  File "/usr/local/lib/python3.7/site-packages/flask/app.py", line 1950, in full_dispatch_request
    rv = self.dispatch_request()
  File "/usr/local/lib/python3.7/site-packages/flask/app.py", line 1936, in dispatch_request
    return self.view_functions[rule.endpoint](**req.view_args)
  File "/workspace/whaaats_new/chatbot.py", line 95, in Message
    dataSend = {
UnboundLocalError: local variable 'dataSend' referenced before assignment
172.17.0.1 - - [16/Jan/2021 10:30:23] "[35m[1mPOST /message HTTP/1.1[0m" 500 -
[2021-01-16 10:30:27,829] ERROR in app: Exception on /message [POST]
Traceback (most recent call last):
  File "/usr/local/lib/python3.7/site-packages/flask/app.py", line 2447, in wsgi_app
    response = self.full_dispatch_request()
  File "/usr/local/lib/python3.7/site-packages/flask/app.py", line 1952, in full_dispatch_request
    rv = self.handle_user_exception(e)
  File "/usr/local/lib/python3.7/site-packages/flask/app.py", line 1821, in handle_user_exception
    reraise(exc_type, exc_value, tb)
  File "/usr/local/lib/python3.7/site-packages/flask/_compat.py", line 39, in reraise
    raise value
  File "/usr/local/lib/python3.7/site-packages/flask/app.py", line 1950, in full_dispatch_request
    rv = self.dispatch_request()
  File "/usr/local/lib/python3.7/site-packages/flask/app.py", line 1936, in dispatch_request
    return self.view_functions[rule.endpoint](**req.view_args)
  File "/workspace/whaaats_new/chatbot.py", line 95, in Message
    dataSend = {
UnboundLocalError: local variable 'dataSend' referenced before assignment
172.17.0.1 - - [16/Jan/2021 10:30:27] "[35m[1mPOST /message HTTP/1.1[0m" 500 -
[2021-01-16 10:30:29,244] ERROR in app: Exception on /message [POST]
Traceback (most recent call last):
  File "/usr/local/lib/python3.7/site-packages/flask/app.py", line 2447, in wsgi_app
    response = self.full_dispatch_request()
  File "/usr/local/lib/python3.7/site-packages/flask/app.py", line 1952, in full_dispatch_request
    rv = self.handle_user_exception(e)
  File "/usr/local/lib/python3.7/site-packages/flask/app.py", line 1821, in handle_user_exception
    reraise(exc_type, exc_value, tb)
  File "/usr/local/lib/python3.7/site-packages/flask/_compat.py", line 39, in reraise
    raise value
  File "/usr/local/lib/python3.7/site-packages/flask/app.py", line 1950, in full_dispatch_request
    rv = self.dispatch_request()
  File "/usr/local/lib/python3.7/site-packages/flask/app.py", line 1936, in dispatch_request
    return self.view_functions[rule.endpoint](**req.view_args)
  File "/workspace/whaaats_new/chatbot.py", line 95, in Message
    dataSend = {
UnboundLocalError: local variable 'dataSend' referenced before assignment
172.17.0.1 - - [16/Jan/2021 10:30:29] "[35m[1mPOST /message HTTP/1.1[0m" 500 -
[2021-01-16 10:30:33,895] ERROR in app: Exception on /message [POST]
Traceback (most recent call last):
  File "/usr/local/lib/python3.7/site-packages/flask/app.py", line 2447, in wsgi_app
    response = self.full_dispatch_request()
  File "/usr/local/lib/python3.7/site-packages/flask/app.py", line 1952, in full_dispatch_request
    rv = self.handle_user_exception(e)
  File "/usr/local/lib/python3.7/site-packages/flask/app.py", line 1821, in handle_user_exception
    reraise(exc_type, exc_value, tb)
  File "/usr/local/lib/python3.7/site-packages/flask/_compat.py", line 39, in reraise
    raise value
  File "/usr/local/lib/python3.7/site-packages/flask/app.py", line 1950, in full_dispatch_request
    rv = self.dispatch_request()
  File "/usr/local/lib/python3.7/site-packages/flask/app.py", line 1936, in dispatch_request
    return self.view_functions[rule.endpoint](**req.view_args)
  File "/workspace/whaaats_new/chatbot.py", line 95, in Message
    dataSend = {
UnboundLocalError: local variable 'dataSend' referenced before assignment
172.17.0.1 - - [16/Jan/2021 10:30:33] "[35m[1mPOST /message HTTP/1.1[0m" 500 -
[2021-01-16 10:30:47,056] ERROR in app: Exception on /message [POST]
Traceback (most recent call last):
  File "/usr/local/lib/python3.7/site-packages/flask/app.py", line 2447, in wsgi_app
    response = self.full_dispatch_request()
  File "/usr/local/lib/python3.7/site-packages/flask/app.py", line 1952, in full_dispatch_request
    rv = self.handle_user_exception(e)
  File "/usr/local/lib/python3.7/site-packages/flask/app.py", line 1821, in handle_user_exception
    reraise(exc_type, exc_value, tb)
  File "/usr/local/lib/python3.7/site-packages/flask/_compat.py", line 39, in reraise
    raise value
  File "/usr/local/lib/python3.7/site-packages/flask/app.py", line 1950, in full_dispatch_request
    rv = self.dispatch_request()
  File "/usr/local/lib/python3.7/site-packages/flask/app.py", line 1936, in dispatch_request
    return self.view_functions[rule.endpoint](**req.view_args)
  File "/workspace/whaaats_new/chatbot.py", line 95, in Message
    dataSend = {
UnboundLocalError: local variable 'dataSend' referenced before assignment
172.17.0.1 - - [16/Jan/2021 10:30:47] "[35m[1mPOST /message HTTP/1.1[0m" 500 -
[2021-01-16 10:30:49,336] ERROR in app: Exception on /message [POST]
Traceback (most recent call last):
  File "/usr/local/lib/python3.7/site-packages/flask/app.py", line 2447, in wsgi_app
    response = self.full_dispatch_request()
  File "/usr/local/lib/python3.7/site-packages/flask/app.py", line 1952, in full_dispatch_request
    rv = self.handle_user_exception(e)
  File "/usr/local/lib/python3.7/site-packages/flask/app.py", line 1821, in handle_user_exception
    reraise(exc_type, exc_value, tb)
  File "/usr/local/lib/python3.7/site-packages/flask/_compat.py", line 39, in reraise
    raise value
  File "/usr/local/lib/python3.7/site-packages/flask/app.py", line 1950, in full_dispatch_request
    rv = self.dispatch_request()
  File "/usr/local/lib/python3.7/site-packages/flask/app.py", line 1936, in dispatch_request
    return self.view_functions[rule.endpoint](**req.view_args)
  File "/workspace/whaaats_new/chatbot.py", line 95, in Message
    dataSend = {
UnboundLocalError: local variable 'dataSend' referenced before assignment
172.17.0.1 - - [16/Jan/2021 10:30:49] "[35m[1mPOST /message HTTP/1.1[0m" 500 -
[2021-01-16 10:30:53,770] ERROR in app: Exception on /message [POST]
Traceback (most recent call last):
  File "/usr/local/lib/python3.7/site-packages/flask/app.py", line 2447, in wsgi_app
    response = self.full_dispatch_request()
  File "/usr/local/lib/python3.7/site-packages/flask/app.py", line 1952, in full_dispatch_request
    rv = self.handle_user_exception(e)
  File "/usr/local/lib/python3.7/site-packages/flask/app.py", line 1821, in handle_user_exception
    reraise(exc_type, exc_value, tb)
  File "/usr/local/lib/python3.7/site-packages/flask/_compat.py", line 39, in reraise
    raise value
  File "/usr/local/lib/python3.7/site-packages/flask/app.py", line 1950, in full_dispatch_request
    rv = self.dispatch_request()
  File "/usr/local/lib/python3.7/site-packages/flask/app.py", line 1936, in dispatch_request
    return self.view_functions[rule.endpoint](**req.view_args)
  File "/workspace/whaaats_new/chatbot.py", line 95, in Message
    dataSend = {
UnboundLocalError: local variable 'dataSend' referenced before assignment
172.17.0.1 - - [16/Jan/2021 10:30:53] "[35m[1mPOST /message HTTP/1.1[0m" 500 -
[2021-01-16 10:30:57,022] ERROR in app: Exception on /message [POST]
Traceback (most recent call last):
  File "/usr/local/lib/python3.7/site-packages/flask/app.py", line 2447, in wsgi_app
    response = self.full_dispatch_request()
  File "/usr/local/lib/python3.7/site-packages/flask/app.py", line 1952, in full_dispatch_request
    rv = self.handle_user_exception(e)
  File "/usr/local/lib/python3.7/site-packages/flask/app.py", line 1821, in handle_user_exception
    reraise(exc_type, exc_value, tb)
  File "/usr/local/lib/python3.7/site-packages/flask/_compat.py", line 39, in reraise
    raise value
  File "/usr/local/lib/python3.7/site-packages/flask/app.py", line 1950, in full_dispatch_request
    rv = self.dispatch_request()
  File "/usr/local/lib/python3.7/site-packages/flask/app.py", line 1936, in dispatch_request
    return self.view_functions[rule.endpoint](**req.view_args)
  File "/workspace/whaaats_new/chatbot.py", line 95, in Message
    dataSend = {
UnboundLocalError: local variable 'dataSend' referenced before assignment
172.17.0.1 - - [16/Jan/2021 10:30:57] "[35m[1mPOST /message HTTP/1.1[0m" 500 -
[2021-01-16 10:34:58,444] ERROR in app: Exception on /message [POST]
Traceback (most recent call last):
  File "/usr/local/lib/python3.7/site-packages/flask/app.py", line 2447, in wsgi_app
    response = self.full_dispatch_request()
  File "/usr/local/lib/python3.7/site-packages/flask/app.py", line 1952, in full_dispatch_request
    rv = self.handle_user_exception(e)
  File "/usr/local/lib/python3.7/site-packages/flask/app.py", line 1821, in handle_user_exception
    reraise(exc_type, exc_value, tb)
  File "/usr/local/lib/python3.7/site-packages/flask/_compat.py", line 39, in reraise
    raise value
  File "/usr/local/lib/python3.7/site-packages/flask/app.py", line 1950, in full_dispatch_request
    rv = self.dispatch_request()
  File "/usr/local/lib/python3.7/site-packages/flask/app.py", line 1936, in dispatch_request
    return self.view_functions[rule.endpoint](**req.view_args)
  File "/workspace/whaaats_new/chatbot.py", line 95, in Message
    dataSend = {
UnboundLocalError: local variable 'dataSend' referenced before assignment
172.17.0.1 - - [16/Jan/2021 10:34:58] "[35m[1mPOST /message HTTP/1.1[0m" 500 -
[2021-01-16 10:35:00,566] ERROR in app: Exception on /message [POST]
Traceback (most recent call last):
  File "/usr/local/lib/python3.7/site-packages/flask/app.py", line 2447, in wsgi_app
    response = self.full_dispatch_request()
  File "/usr/local/lib/python3.7/site-packages/flask/app.py", line 1952, in full_dispatch_request
    rv = self.handle_user_exception(e)
  File "/usr/local/lib/python3.7/site-packages/flask/app.py", line 1821, in handle_user_exception
    reraise(exc_type, exc_value, tb)
  File "/usr/local/lib/python3.7/site-packages/flask/_compat.py", line 39, in reraise
    raise value
  File "/usr/local/lib/python3.7/site-packages/flask/app.py", line 1950, in full_dispatch_request
    rv = self.dispatch_request()
  File "/usr/local/lib/python3.7/site-packages/flask/app.py", line 1936, in dispatch_request
    return self.view_functions[rule.endpoint](**req.view_args)
  File "/workspace/whaaats_new/chatbot.py", line 95, in Message
    dataSend = {
UnboundLocalError: local variable 'dataSend' referenced before assignment
172.17.0.1 - - [16/Jan/2021 10:35:00] "[35m[1mPOST /message HTTP/1.1[0m" 500 -
[2021-01-16 10:35:01,035] ERROR in app: Exception on /message [POST]
Traceback (most recent call last):
  File "/usr/local/lib/python3.7/site-packages/flask/app.py", line 2447, in wsgi_app
    response = self.full_dispatch_request()
  File "/usr/local/lib/python3.7/site-packages/flask/app.py", line 1952, in full_dispatch_request
    rv = self.handle_user_exception(e)
  File "/usr/local/lib/python3.7/site-packages/flask/app.py", line 1821, in handle_user_exception
    reraise(exc_type, exc_value, tb)
  File "/usr/local/lib/python3.7/site-packages/flask/_compat.py", line 39, in reraise
    raise value
  File "/usr/local/lib/python3.7/site-packages/flask/app.py", line 1950, in full_dispatch_request
    rv = self.dispatch_request()
  File "/usr/local/lib/python3.7/site-packages/flask/app.py", line 1936, in dispatch_request
    return self.view_functions[rule.endpoint](**req.view_args)
  File "/workspace/whaaats_new/chatbot.py", line 95, in Message
    dataSend = {
UnboundLocalError: local variable 'dataSend' referenced before assignment
172.17.0.1 - - [16/Jan/2021 10:35:01] "[35m[1mPOST /message HTTP/1.1[0m" 500 -
[2021-01-16 10:35:02,381] ERROR in app: Exception on /message [POST]
Traceback (most recent call last):
  File "/usr/local/lib/python3.7/site-packages/flask/app.py", line 2447, in wsgi_app
    response = self.full_dispatch_request()
  File "/usr/local/lib/python3.7/site-packages/flask/app.py", line 1952, in full_dispatch_request
    rv = self.handle_user_exception(e)
  File "/usr/local/lib/python3.7/site-packages/flask/app.py", line 1821, in handle_user_exception
    reraise(exc_type, exc_value, tb)
  File "/usr/local/lib/python3.7/site-packages/flask/_compat.py", line 39, in reraise
    raise value
  File "/usr/local/lib/python3.7/site-packages/flask/app.py", line 1950, in full_dispatch_request
    rv = self.dispatch_request()
  File "/usr/local/lib/python3.7/site-packages/flask/app.py", line 1936, in dispatch_request
    return self.view_functions[rule.endpoint](**req.view_args)
  File "/workspace/whaaats_new/chatbot.py", line 95, in Message
    dataSend = {
UnboundLocalError: local variable 'dataSend' referenced before assignment
172.17.0.1 - - [16/Jan/2021 10:35:02] "[35m[1mPOST /message HTTP/1.1[0m" 500 -
[2021-01-16 10:35:04,213] ERROR in app: Exception on /message [POST]
Traceback (most recent call last):
  File "/usr/local/lib/python3.7/site-packages/flask/app.py", line 2447, in wsgi_app
    response = self.full_dispatch_request()
  File "/usr/local/lib/python3.7/site-packages/flask/app.py", line 1952, in full_dispatch_request
    rv = self.handle_user_exception(e)
  File "/usr/local/lib/python3.7/site-packages/flask/app.py", line 1821, in handle_user_exception
    reraise(exc_type, exc_value, tb)
  File "/usr/local/lib/python3.7/site-packages/flask/_compat.py", line 39, in reraise
    raise value
  File "/usr/local/lib/python3.7/site-packages/flask/app.py", line 1950, in full_dispatch_request
    rv = self.dispatch_request()
  File "/usr/local/lib/python3.7/site-packages/flask/app.py", line 1936, in dispatch_request
    return self.view_functions[rule.endpoint](**req.view_args)
  File "/workspace/whaaats_new/chatbot.py", line 95, in Message
    dataSend = {
UnboundLocalError: local variable 'dataSend' referenced before assignment
172.17.0.1 - - [16/Jan/2021 10:35:04] "[35m[1mPOST /message HTTP/1.1[0m" 500 -
[2021-01-16 10:35:04,387] ERROR in app: Exception on /message [POST]
Traceback (most recent call last):
  File "/usr/local/lib/python3.7/site-packages/flask/app.py", line 2447, in wsgi_app
    response = self.full_dispatch_request()
  File "/usr/local/lib/python3.7/site-packages/flask/app.py", line 1952, in full_dispatch_request
    rv = self.handle_user_exception(e)
  File "/usr/local/lib/python3.7/site-packages/flask/app.py", line 1821, in handle_user_exception
    reraise(exc_type, exc_value, tb)
  File "/usr/local/lib/python3.7/site-packages/flask/_compat.py", line 39, in reraise
    raise value
  File "/usr/local/lib/python3.7/site-packages/flask/app.py", line 1950, in full_dispatch_request
    rv = self.dispatch_request()
  File "/usr/local/lib/python3.7/site-packages/flask/app.py", line 1936, in dispatch_request
    return self.view_functions[rule.endpoint](**req.view_args)
  File "/workspace/whaaats_new/chatbot.py", line 95, in Message
    dataSend = {
UnboundLocalError: local variable 'dataSend' referenced before assignment
172.17.0.1 - - [16/Jan/2021 10:35:04] "[35m[1mPOST /message HTTP/1.1[0m" 500 -
[2021-01-16 10:35:09,498] ERROR in app: Exception on /message [POST]
Traceback (most recent call last):
  File "/usr/local/lib/python3.7/site-packages/flask/app.py", line 2447, in wsgi_app
    response = self.full_dispatch_request()
  File "/usr/local/lib/python3.7/site-packages/flask/app.py", line 1952, in full_dispatch_request
    rv = self.handle_user_exception(e)
  File "/usr/local/lib/python3.7/site-packages/flask/app.py", line 1821, in handle_user_exception
    reraise(exc_type, exc_value, tb)
  File "/usr/local/lib/python3.7/site-packages/flask/_compat.py", line 39, in reraise
    raise value
  File "/usr/local/lib/python3.7/site-packages/flask/app.py", line 1950, in full_dispatch_request
    rv = self.dispatch_request()
  File "/usr/local/lib/python3.7/site-packages/flask/app.py", line 1936, in dispatch_request
    return self.view_functions[rule.endpoint](**req.view_args)
  File "/workspace/whaaats_new/chatbot.py", line 95, in Message
    dataSend = {
UnboundLocalError: local variable 'dataSend' referenced before assignment
172.17.0.1 - - [16/Jan/2021 10:35:09] "[35m[1mPOST /message HTTP/1.1[0m" 500 -
[2021-01-16 10:35:20,871] ERROR in app: Exception on /message [POST]
Traceback (most recent call last):
  File "/usr/local/lib/python3.7/site-packages/flask/app.py", line 2447, in wsgi_app
    response = self.full_dispatch_request()
  File "/usr/local/lib/python3.7/site-packages/flask/app.py", line 1952, in full_dispatch_request
    rv = self.handle_user_exception(e)
  File "/usr/local/lib/python3.7/site-packages/flask/app.py", line 1821, in handle_user_exception
    reraise(exc_type, exc_value, tb)
  File "/usr/local/lib/python3.7/site-packages/flask/_compat.py", line 39, in reraise
    raise value
  File "/usr/local/lib/python3.7/site-packages/flask/app.py", line 1950, in full_dispatch_request
    rv = self.dispatch_request()
  File "/usr/local/lib/python3.7/site-packages/flask/app.py", line 1936, in dispatch_request
    return self.view_functions[rule.endpoint](**req.view_args)
  File "/workspace/whaaats_new/chatbot.py", line 95, in Message
    dataSend = {
UnboundLocalError: local variable 'dataSend' referenced before assignment
172.17.0.1 - - [16/Jan/2021 10:35:20] "[35m[1mPOST /message HTTP/1.1[0m" 500 -
172.17.0.1 - - [16/Jan/2021 10:35:51] "[37mPOST /message HTTP/1.1[0m" 200 -
[2021-01-16 10:35:54,840] ERROR in app: Exception on /message [POST]
Traceback (most recent call last):
  File "/usr/local/lib/python3.7/site-packages/flask/app.py", line 2447, in wsgi_app
    response = self.full_dispatch_request()
  File "/usr/local/lib/python3.7/site-packages/flask/app.py", line 1952, in full_dispatch_request
    rv = self.handle_user_exception(e)
  File "/usr/local/lib/python3.7/site-packages/flask/app.py", line 1821, in handle_user_exception
    reraise(exc_type, exc_value, tb)
  File "/usr/local/lib/python3.7/site-packages/flask/_compat.py", line 39, in reraise
    raise value
  File "/usr/local/lib/python3.7/site-packages/flask/app.py", line 1950, in full_dispatch_request
    rv = self.dispatch_request()
  File "/usr/local/lib/python3.7/site-packages/flask/app.py", line 1936, in dispatch_request
    return self.view_functions[rule.endpoint](**req.view_args)
  File "/workspace/whaaats_new/chatbot.py", line 95, in Message
    dataSend = {
UnboundLocalError: local variable 'dataSend' referenced before assignment
172.17.0.1 - - [16/Jan/2021 10:35:54] "[35m[1mPOST /message HTTP/1.1[0m" 500 -
[2021-01-16 10:36:48,750] ERROR in app: Exception on /message [POST]
Traceback (most recent call last):
  File "/usr/local/lib/python3.7/site-packages/flask/app.py", line 2447, in wsgi_app
    response = self.full_dispatch_request()
  File "/usr/local/lib/python3.7/site-packages/flask/app.py", line 1952, in full_dispatch_request
    rv = self.handle_user_exception(e)
  File "/usr/local/lib/python3.7/site-packages/flask/app.py", line 1821, in handle_user_exception
    reraise(exc_type, exc_value, tb)
  File "/usr/local/lib/python3.7/site-packages/flask/_compat.py", line 39, in reraise
    raise value
  File "/usr/local/lib/python3.7/site-packages/flask/app.py", line 1950, in full_dispatch_request
    rv = self.dispatch_request()
  File "/usr/local/lib/python3.7/site-packages/flask/app.py", line 1936, in dispatch_request
    return self.view_functions[rule.endpoint](**req.view_args)
  File "/workspace/whaaats_new/chatbot.py", line 95, in Message
    dataSend = {
UnboundLocalError: local variable 'dataSend' referenced before assignment
172.17.0.1 - - [16/Jan/2021 10:36:48] "[35m[1mPOST /message HTTP/1.1[0m" 500 -
[2021-01-16 10:36:51,670] ERROR in app: Exception on /message [POST]
Traceback (most recent call last):
  File "/usr/local/lib/python3.7/site-packages/flask/app.py", line 2447, in wsgi_app
    response = self.full_dispatch_request()
  File "/usr/local/lib/python3.7/site-packages/flask/app.py", line 1952, in full_dispatch_request
    rv = self.handle_user_exception(e)
  File "/usr/local/lib/python3.7/site-packages/flask/app.py", line 1821, in handle_user_exception
    reraise(exc_type, exc_value, tb)
  File "/usr/local/lib/python3.7/site-packages/flask/_compat.py", line 39, in reraise
    raise value
  File "/usr/local/lib/python3.7/site-packages/flask/app.py", line 1950, in full_dispatch_request
    rv = self.dispatch_request()
  File "/usr/local/lib/python3.7/site-packages/flask/app.py", line 1936, in dispatch_request
    return self.view_functions[rule.endpoint](**req.view_args)
  File "/workspace/whaaats_new/chatbot.py", line 95, in Message
    dataSend = {
UnboundLocalError: local variable 'dataSend' referenced before assignment
172.17.0.1 - - [16/Jan/2021 10:36:51] "[35m[1mPOST /message HTTP/1.1[0m" 500 -
[2021-01-16 10:36:51,805] ERROR in app: Exception on /message [POST]
Traceback (most recent call last):
  File "/usr/local/lib/python3.7/site-packages/flask/app.py", line 2447, in wsgi_app
    response = self.full_dispatch_request()
  File "/usr/local/lib/python3.7/site-packages/flask/app.py", line 1952, in full_dispatch_request
    rv = self.handle_user_exception(e)
  File "/usr/local/lib/python3.7/site-packages/flask/app.py", line 1821, in handle_user_exception
    reraise(exc_type, exc_value, tb)
  File "/usr/local/lib/python3.7/site-packages/flask/_compat.py", line 39, in reraise
    raise value
  File "/usr/local/lib/python3.7/site-packages/flask/app.py", line 1950, in full_dispatch_request
    rv = self.dispatch_request()
  File "/usr/local/lib/python3.7/site-packages/flask/app.py", line 1936, in dispatch_request
    return self.view_functions[rule.endpoint](**req.view_args)
  File "/workspace/whaaats_new/chatbot.py", line 95, in Message
    dataSend = {
UnboundLocalError: local variable 'dataSend' referenced before assignment
172.17.0.1 - - [16/Jan/2021 10:36:51] "[35m[1mPOST /message HTTP/1.1[0m" 500 -
[2021-01-16 10:37:29,091] ERROR in app: Exception on /message [POST]
Traceback (most recent call last):
  File "/usr/local/lib/python3.7/site-packages/flask/app.py", line 2447, in wsgi_app
    response = self.full_dispatch_request()
  File "/usr/local/lib/python3.7/site-packages/flask/app.py", line 1952, in full_dispatch_request
    rv = self.handle_user_exception(e)
  File "/usr/local/lib/python3.7/site-packages/flask/app.py", line 1821, in handle_user_exception
    reraise(exc_type, exc_value, tb)
  File "/usr/local/lib/python3.7/site-packages/flask/_compat.py", line 39, in reraise
    raise value
  File "/usr/local/lib/python3.7/site-packages/flask/app.py", line 1950, in full_dispatch_request
    rv = self.dispatch_request()
  File "/usr/local/lib/python3.7/site-packages/flask/app.py", line 1936, in dispatch_request
    return self.view_functions[rule.endpoint](**req.view_args)
  File "/workspace/whaaats_new/chatbot.py", line 95, in Message
    dataSend = {
UnboundLocalError: local variable 'dataSend' referenced before assignment
172.17.0.1 - - [16/Jan/2021 10:37:29] "[35m[1mPOST /message HTTP/1.1[0m" 500 -
[2021-01-16 10:39:23,853] ERROR in app: Exception on /message [POST]
Traceback (most recent call last):
  File "/usr/local/lib/python3.7/site-packages/flask/app.py", line 2447, in wsgi_app
    response = self.full_dispatch_request()
  File "/usr/local/lib/python3.7/site-packages/flask/app.py", line 1952, in full_dispatch_request
    rv = self.handle_user_exception(e)
  File "/usr/local/lib/python3.7/site-packages/flask/app.py", line 1821, in handle_user_exception
    reraise(exc_type, exc_value, tb)
  File "/usr/local/lib/python3.7/site-packages/flask/_compat.py", line 39, in reraise
    raise value
  File "/usr/local/lib/python3.7/site-packages/flask/app.py", line 1950, in full_dispatch_request
    rv = self.dispatch_request()
  File "/usr/local/lib/python3.7/site-packages/flask/app.py", line 1936, in dispatch_request
    return self.view_functions[rule.endpoint](**req.view_args)
  File "/workspace/whaaats_new/chatbot.py", line 95, in Message
    brand = pd.read_csv("entity_brand.csv")
UnboundLocalError: local variable 'dataSend' referenced before assignment
172.17.0.1 - - [16/Jan/2021 10:39:23] "[35m[1mPOST /message HTTP/1.1[0m" 500 -
[2021-01-16 10:39:25,471] ERROR in app: Exception on /message [POST]
Traceback (most recent call last):
  File "/usr/local/lib/python3.7/site-packages/flask/app.py", line 2447, in wsgi_app
    response = self.full_dispatch_request()
  File "/usr/local/lib/python3.7/site-packages/flask/app.py", line 1952, in full_dispatch_request
    rv = self.handle_user_exception(e)
  File "/usr/local/lib/python3.7/site-packages/flask/app.py", line 1821, in handle_user_exception
    reraise(exc_type, exc_value, tb)
  File "/usr/local/lib/python3.7/site-packages/flask/_compat.py", line 39, in reraise
    raise value
  File "/usr/local/lib/python3.7/site-packages/flask/app.py", line 1950, in full_dispatch_request
    rv = self.dispatch_request()
  File "/usr/local/lib/python3.7/site-packages/flask/app.py", line 1936, in dispatch_request
    return self.view_functions[rule.endpoint](**req.view_args)
  File "/workspace/whaaats_new/chatbot.py", line 95, in Message
    brand = pd.read_csv("entity_brand.csv")
UnboundLocalError: local variable 'dataSend' referenced before assignment
172.17.0.1 - - [16/Jan/2021 10:39:25] "[35m[1mPOST /message HTTP/1.1[0m" 500 -
[2021-01-16 10:39:25,698] ERROR in app: Exception on /message [POST]
Traceback (most recent call last):
  File "/usr/local/lib/python3.7/site-packages/flask/app.py", line 2447, in wsgi_app
    response = self.full_dispatch_request()
  File "/usr/local/lib/python3.7/site-packages/flask/app.py", line 1952, in full_dispatch_request
    rv = self.handle_user_exception(e)
  File "/usr/local/lib/python3.7/site-packages/flask/app.py", line 1821, in handle_user_exception
    reraise(exc_type, exc_value, tb)
  File "/usr/local/lib/python3.7/site-packages/flask/_compat.py", line 39, in reraise
    raise value
  File "/usr/local/lib/python3.7/site-packages/flask/app.py", line 1950, in full_dispatch_request
    rv = self.dispatch_request()
  File "/usr/local/lib/python3.7/site-packages/flask/app.py", line 1936, in dispatch_request
    return self.view_functions[rule.endpoint](**req.view_args)
  File "/workspace/whaaats_new/chatbot.py", line 95, in Message
    brand = pd.read_csv("entity_brand.csv")
UnboundLocalError: local variable 'dataSend' referenced before assignment
172.17.0.1 - - [16/Jan/2021 10:39:25] "[35m[1mPOST /message HTTP/1.1[0m" 500 -
[2021-01-16 10:39:25,748] ERROR in app: Exception on /message [POST]
Traceback (most recent call last):
  File "/usr/local/lib/python3.7/site-packages/flask/app.py", line 2447, in wsgi_app
    response = self.full_dispatch_request()
  File "/usr/local/lib/python3.7/site-packages/flask/app.py", line 1952, in full_dispatch_request
    rv = self.handle_user_exception(e)
  File "/usr/local/lib/python3.7/site-packages/flask/app.py", line 1821, in handle_user_exception
    reraise(exc_type, exc_value, tb)
  File "/usr/local/lib/python3.7/site-packages/flask/_compat.py", line 39, in reraise
    raise value
  File "/usr/local/lib/python3.7/site-packages/flask/app.py", line 1950, in full_dispatch_request
    rv = self.dispatch_request()
  File "/usr/local/lib/python3.7/site-packages/flask/app.py", line 1936, in dispatch_request
    return self.view_functions[rule.endpoint](**req.view_args)
  File "/workspace/whaaats_new/chatbot.py", line 95, in Message
    brand = pd.read_csv("entity_brand.csv")
UnboundLocalError: local variable 'dataSend' referenced before assignment
172.17.0.1 - - [16/Jan/2021 10:39:25] "[35m[1mPOST /message HTTP/1.1[0m" 500 -
[2021-01-16 10:39:26,834] ERROR in app: Exception on /message [POST]
Traceback (most recent call last):
  File "/usr/local/lib/python3.7/site-packages/flask/app.py", line 2447, in wsgi_app
    response = self.full_dispatch_request()
  File "/usr/local/lib/python3.7/site-packages/flask/app.py", line 1952, in full_dispatch_request
    rv = self.handle_user_exception(e)
  File "/usr/local/lib/python3.7/site-packages/flask/app.py", line 1821, in handle_user_exception
    reraise(exc_type, exc_value, tb)
  File "/usr/local/lib/python3.7/site-packages/flask/_compat.py", line 39, in reraise
    raise value
  File "/usr/local/lib/python3.7/site-packages/flask/app.py", line 1950, in full_dispatch_request
    rv = self.dispatch_request()
  File "/usr/local/lib/python3.7/site-packages/flask/app.py", line 1936, in dispatch_request
    return self.view_functions[rule.endpoint](**req.view_args)
  File "/workspace/whaaats_new/chatbot.py", line 95, in Message
    brand = pd.read_csv("entity_brand.csv")
UnboundLocalError: local variable 'dataSend' referenced before assignment
172.17.0.1 - - [16/Jan/2021 10:39:26] "[35m[1mPOST /message HTTP/1.1[0m" 500 -
[2021-01-16 10:40:21,971] ERROR in app: Exception on /message [POST]
Traceback (most recent call last):
  File "/usr/local/lib/python3.7/site-packages/flask/app.py", line 2447, in wsgi_app
    response = self.full_dispatch_request()
  File "/usr/local/lib/python3.7/site-packages/flask/app.py", line 1952, in full_dispatch_request
    rv = self.handle_user_exception(e)
  File "/usr/local/lib/python3.7/site-packages/flask/app.py", line 1821, in handle_user_exception
    reraise(exc_type, exc_value, tb)
  File "/usr/local/lib/python3.7/site-packages/flask/_compat.py", line 39, in reraise
    raise value
  File "/usr/local/lib/python3.7/site-packages/flask/app.py", line 1950, in full_dispatch_request
    rv = self.dispatch_request()
  File "/usr/local/lib/python3.7/site-packages/flask/app.py", line 1936, in dispatch_request
    return self.view_functions[rule.endpoint](**req.view_args)
  File "/workspace/whaaats_new/chatbot.py", line 95, in Message
    brand = pd.read_csv("entity_brand.csv")
UnboundLocalError: local variable 'dataSend' referenced before assignment
172.17.0.1 - - [16/Jan/2021 10:40:21] "[35m[1mPOST /message HTTP/1.1[0m" 500 -
[2021-01-16 10:40:25,018] ERROR in app: Exception on /message [POST]
Traceback (most recent call last):
  File "/usr/local/lib/python3.7/site-packages/flask/app.py", line 2447, in wsgi_app
    response = self.full_dispatch_request()
  File "/usr/local/lib/python3.7/site-packages/flask/app.py", line 1952, in full_dispatch_request
    rv = self.handle_user_exception(e)
  File "/usr/local/lib/python3.7/site-packages/flask/app.py", line 1821, in handle_user_exception
    reraise(exc_type, exc_value, tb)
  File "/usr/local/lib/python3.7/site-packages/flask/_compat.py", line 39, in reraise
    raise value
  File "/usr/local/lib/python3.7/site-packages/flask/app.py", line 1950, in full_dispatch_request
    rv = self.dispatch_request()
  File "/usr/local/lib/python3.7/site-packages/flask/app.py", line 1936, in dispatch_request
    return self.view_functions[rule.endpoint](**req.view_args)
  File "/workspace/whaaats_new/chatbot.py", line 95, in Message
    brand = pd.read_csv("entity_brand.csv")
UnboundLocalError: local variable 'dataSend' referenced before assignment
172.17.0.1 - - [16/Jan/2021 10:40:25] "[35m[1mPOST /message HTTP/1.1[0m" 500 -
[2021-01-16 10:40:25,094] ERROR in app: Exception on /message [POST]
Traceback (most recent call last):
  File "/usr/local/lib/python3.7/site-packages/flask/app.py", line 2447, in wsgi_app
    response = self.full_dispatch_request()
  File "/usr/local/lib/python3.7/site-packages/flask/app.py", line 1952, in full_dispatch_request
    rv = self.handle_user_exception(e)
  File "/usr/local/lib/python3.7/site-packages/flask/app.py", line 1821, in handle_user_exception
    reraise(exc_type, exc_value, tb)
  File "/usr/local/lib/python3.7/site-packages/flask/_compat.py", line 39, in reraise
    raise value
  File "/usr/local/lib/python3.7/site-packages/flask/app.py", line 1950, in full_dispatch_request
    rv = self.dispatch_request()
  File "/usr/local/lib/python3.7/site-packages/flask/app.py", line 1936, in dispatch_request
    return self.view_functions[rule.endpoint](**req.view_args)
  File "/workspace/whaaats_new/chatbot.py", line 95, in Message
    brand = pd.read_csv("entity_brand.csv")
UnboundLocalError: local variable 'dataSend' referenced before assignment
172.17.0.1 - - [16/Jan/2021 10:40:25] "[35m[1mPOST /message HTTP/1.1[0m" 500 -
[2021-01-16 10:40:26,144] ERROR in app: Exception on /message [POST]
Traceback (most recent call last):
  File "/usr/local/lib/python3.7/site-packages/flask/app.py", line 2447, in wsgi_app
    response = self.full_dispatch_request()
  File "/usr/local/lib/python3.7/site-packages/flask/app.py", line 1952, in full_dispatch_request
    rv = self.handle_user_exception(e)
  File "/usr/local/lib/python3.7/site-packages/flask/app.py", line 1821, in handle_user_exception
    reraise(exc_type, exc_value, tb)
  File "/usr/local/lib/python3.7/site-packages/flask/_compat.py", line 39, in reraise
    raise value
  File "/usr/local/lib/python3.7/site-packages/flask/app.py", line 1950, in full_dispatch_request
    rv = self.dispatch_request()
  File "/usr/local/lib/python3.7/site-packages/flask/app.py", line 1936, in dispatch_request
    return self.view_functions[rule.endpoint](**req.view_args)
  File "/workspace/whaaats_new/chatbot.py", line 95, in Message
    brand = pd.read_csv("entity_brand.csv")
UnboundLocalError: local variable 'dataSend' referenced before assignment
172.17.0.1 - - [16/Jan/2021 10:40:26] "[35m[1mPOST /message HTTP/1.1[0m" 500 -
[2021-01-16 10:40:26,234] ERROR in app: Exception on /message [POST]
Traceback (most recent call last):
  File "/usr/local/lib/python3.7/site-packages/flask/app.py", line 2447, in wsgi_app
    response = self.full_dispatch_request()
  File "/usr/local/lib/python3.7/site-packages/flask/app.py", line 1952, in full_dispatch_request
    rv = self.handle_user_exception(e)
  File "/usr/local/lib/python3.7/site-packages/flask/app.py", line 1821, in handle_user_exception
    reraise(exc_type, exc_value, tb)
  File "/usr/local/lib/python3.7/site-packages/flask/_compat.py", line 39, in reraise
    raise value
  File "/usr/local/lib/python3.7/site-packages/flask/app.py", line 1950, in full_dispatch_request
    rv = self.dispatch_request()
  File "/usr/local/lib/python3.7/site-packages/flask/app.py", line 1936, in dispatch_request
    return self.view_functions[rule.endpoint](**req.view_args)
  File "/workspace/whaaats_new/chatbot.py", line 95, in Message
    brand = pd.read_csv("entity_brand.csv")
UnboundLocalError: local variable 'dataSend' referenced before assignment
172.17.0.1 - - [16/Jan/2021 10:40:26] "[35m[1mPOST /message HTTP/1.1[0m" 500 -
172.17.0.1 - - [16/Jan/2021 10:40:30] "[37mPOST /message HTTP/1.1[0m" 200 -
[2021-01-16 10:41:09,324] ERROR in app: Exception on /message [POST]
Traceback (most recent call last):
  File "/usr/local/lib/python3.7/site-packages/flask/app.py", line 2447, in wsgi_app
    response = self.full_dispatch_request()
  File "/usr/local/lib/python3.7/site-packages/flask/app.py", line 1952, in full_dispatch_request
    rv = self.handle_user_exception(e)
  File "/usr/local/lib/python3.7/site-packages/flask/app.py", line 1821, in handle_user_exception
    reraise(exc_type, exc_value, tb)
  File "/usr/local/lib/python3.7/site-packages/flask/_compat.py", line 39, in reraise
    raise value
  File "/usr/local/lib/python3.7/site-packages/flask/app.py", line 1950, in full_dispatch_request
    rv = self.dispatch_request()
  File "/usr/local/lib/python3.7/site-packages/flask/app.py", line 1936, in dispatch_request
    return self.view_functions[rule.endpoint](**req.view_args)
  File "/workspace/whaaats_new/chatbot.py", line 95, in Message
    brand = pd.read_csv("entity_brand.csv")
UnboundLocalError: local variable 'dataSend' referenced before assignment
172.17.0.1 - - [16/Jan/2021 10:41:09] "[35m[1mPOST /message HTTP/1.1[0m" 500 -
[2021-01-16 10:41:09,514] ERROR in app: Exception on /message [POST]
Traceback (most recent call last):
  File "/usr/local/lib/python3.7/site-packages/flask/app.py", line 2447, in wsgi_app
    response = self.full_dispatch_request()
  File "/usr/local/lib/python3.7/site-packages/flask/app.py", line 1952, in full_dispatch_request
    rv = self.handle_user_exception(e)
  File "/usr/local/lib/python3.7/site-packages/flask/app.py", line 1821, in handle_user_exception
    reraise(exc_type, exc_value, tb)
  File "/usr/local/lib/python3.7/site-packages/flask/_compat.py", line 39, in reraise
    raise value
  File "/usr/local/lib/python3.7/site-packages/flask/app.py", line 1950, in full_dispatch_request
    rv = self.dispatch_request()
  File "/usr/local/lib/python3.7/site-packages/flask/app.py", line 1936, in dispatch_request
    return self.view_functions[rule.endpoint](**req.view_args)
  File "/workspace/whaaats_new/chatbot.py", line 95, in Message
    brand = pd.read_csv("entity_brand.csv")
UnboundLocalError: local variable 'dataSend' referenced before assignment
172.17.0.1 - - [16/Jan/2021 10:41:09] "[35m[1mPOST /message HTTP/1.1[0m" 500 -
[2021-01-16 10:41:10,146] ERROR in app: Exception on /message [POST]
Traceback (most recent call last):
  File "/usr/local/lib/python3.7/site-packages/flask/app.py", line 2447, in wsgi_app
    response = self.full_dispatch_request()
  File "/usr/local/lib/python3.7/site-packages/flask/app.py", line 1952, in full_dispatch_request
    rv = self.handle_user_exception(e)
  File "/usr/local/lib/python3.7/site-packages/flask/app.py", line 1821, in handle_user_exception
    reraise(exc_type, exc_value, tb)
  File "/usr/local/lib/python3.7/site-packages/flask/_compat.py", line 39, in reraise
    raise value
  File "/usr/local/lib/python3.7/site-packages/flask/app.py", line 1950, in full_dispatch_request
    rv = self.dispatch_request()
  File "/usr/local/lib/python3.7/site-packages/flask/app.py", line 1936, in dispatch_request
    return self.view_functions[rule.endpoint](**req.view_args)
  File "/workspace/whaaats_new/chatbot.py", line 95, in Message
    brand = pd.read_csv("entity_brand.csv")
UnboundLocalError: local variable 'dataSend' referenced before assignment
172.17.0.1 - - [16/Jan/2021 10:41:10] "[35m[1mPOST /message HTTP/1.1[0m" 500 -
[2021-01-16 10:41:10,476] ERROR in app: Exception on /message [POST]
Traceback (most recent call last):
  File "/usr/local/lib/python3.7/site-packages/flask/app.py", line 2447, in wsgi_app
    response = self.full_dispatch_request()
  File "/usr/local/lib/python3.7/site-packages/flask/app.py", line 1952, in full_dispatch_request
    rv = self.handle_user_exception(e)
  File "/usr/local/lib/python3.7/site-packages/flask/app.py", line 1821, in handle_user_exception
    reraise(exc_type, exc_value, tb)
  File "/usr/local/lib/python3.7/site-packages/flask/_compat.py", line 39, in reraise
    raise value
  File "/usr/local/lib/python3.7/site-packages/flask/app.py", line 1950, in full_dispatch_request
    rv = self.dispatch_request()
  File "/usr/local/lib/python3.7/site-packages/flask/app.py", line 1936, in dispatch_request
    return self.view_functions[rule.endpoint](**req.view_args)
  File "/workspace/whaaats_new/chatbot.py", line 95, in Message
    brand = pd.read_csv("entity_brand.csv")
UnboundLocalError: local variable 'dataSend' referenced before assignment
172.17.0.1 - - [16/Jan/2021 10:41:10] "[35m[1mPOST /message HTTP/1.1[0m" 500 -
[2021-01-16 10:41:16,867] ERROR in app: Exception on /message [POST]
Traceback (most recent call last):
  File "/usr/local/lib/python3.7/site-packages/flask/app.py", line 2447, in wsgi_app
    response = self.full_dispatch_request()
  File "/usr/local/lib/python3.7/site-packages/flask/app.py", line 1952, in full_dispatch_request
    rv = self.handle_user_exception(e)
  File "/usr/local/lib/python3.7/site-packages/flask/app.py", line 1821, in handle_user_exception
    reraise(exc_type, exc_value, tb)
  File "/usr/local/lib/python3.7/site-packages/flask/_compat.py", line 39, in reraise
    raise value
  File "/usr/local/lib/python3.7/site-packages/flask/app.py", line 1950, in full_dispatch_request
    rv = self.dispatch_request()
  File "/usr/local/lib/python3.7/site-packages/flask/app.py", line 1936, in dispatch_request
    return self.view_functions[rule.endpoint](**req.view_args)
  File "/workspace/whaaats_new/chatbot.py", line 95, in Message
    brand = pd.read_csv("entity_brand.csv")
UnboundLocalError: local variable 'dataSend' referenced before assignment
172.17.0.1 - - [16/Jan/2021 10:41:16] "[35m[1mPOST /message HTTP/1.1[0m" 500 -
[2021-01-16 10:41:24,741] ERROR in app: Exception on /message [POST]
Traceback (most recent call last):
  File "/usr/local/lib/python3.7/site-packages/flask/app.py", line 2447, in wsgi_app
    response = self.full_dispatch_request()
  File "/usr/local/lib/python3.7/site-packages/flask/app.py", line 1952, in full_dispatch_request
    rv = self.handle_user_exception(e)
  File "/usr/local/lib/python3.7/site-packages/flask/app.py", line 1821, in handle_user_exception
    reraise(exc_type, exc_value, tb)
  File "/usr/local/lib/python3.7/site-packages/flask/_compat.py", line 39, in reraise
    raise value
  File "/usr/local/lib/python3.7/site-packages/flask/app.py", line 1950, in full_dispatch_request
    rv = self.dispatch_request()
  File "/usr/local/lib/python3.7/site-packages/flask/app.py", line 1936, in dispatch_request
    return self.view_functions[rule.endpoint](**req.view_args)
  File "/workspace/whaaats_new/chatbot.py", line 95, in Message
    brand = pd.read_csv("entity_brand.csv")
UnboundLocalError: local variable 'dataSend' referenced before assignment
172.17.0.1 - - [16/Jan/2021 10:41:24] "[35m[1mPOST /message HTTP/1.1[0m" 500 -
172.17.0.1 - - [16/Jan/2021 10:41:29] "[37mPOST /message HTTP/1.1[0m" 200 -
[2021-01-16 10:41:32,055] ERROR in app: Exception on /message [POST]
Traceback (most recent call last):
  File "/usr/local/lib/python3.7/site-packages/flask/app.py", line 2447, in wsgi_app
    response = self.full_dispatch_request()
  File "/usr/local/lib/python3.7/site-packages/flask/app.py", line 1952, in full_dispatch_request
    rv = self.handle_user_exception(e)
  File "/usr/local/lib/python3.7/site-packages/flask/app.py", line 1821, in handle_user_exception
    reraise(exc_type, exc_value, tb)
  File "/usr/local/lib/python3.7/site-packages/flask/_compat.py", line 39, in reraise
    raise value
  File "/usr/local/lib/python3.7/site-packages/flask/app.py", line 1950, in full_dispatch_request
    rv = self.dispatch_request()
  File "/usr/local/lib/python3.7/site-packages/flask/app.py", line 1936, in dispatch_request
    return self.view_functions[rule.endpoint](**req.view_args)
  File "/workspace/whaaats_new/chatbot.py", line 95, in Message
    brand = pd.read_csv("entity_brand.csv")
UnboundLocalError: local variable 'dataSend' referenced before assignment
172.17.0.1 - - [16/Jan/2021 10:41:32] "[35m[1mPOST /message HTTP/1.1[0m" 500 -
[2021-01-16 10:41:59,410] ERROR in app: Exception on /message [POST]
Traceback (most recent call last):
  File "/usr/local/lib/python3.7/site-packages/flask/app.py", line 2447, in wsgi_app
    response = self.full_dispatch_request()
  File "/usr/local/lib/python3.7/site-packages/flask/app.py", line 1952, in full_dispatch_request
    rv = self.handle_user_exception(e)
  File "/usr/local/lib/python3.7/site-packages/flask/app.py", line 1821, in handle_user_exception
    reraise(exc_type, exc_value, tb)
  File "/usr/local/lib/python3.7/site-packages/flask/_compat.py", line 39, in reraise
    raise value
  File "/usr/local/lib/python3.7/site-packages/flask/app.py", line 1950, in full_dispatch_request
    rv = self.dispatch_request()
  File "/usr/local/lib/python3.7/site-packages/flask/app.py", line 1936, in dispatch_request
    return self.view_functions[rule.endpoint](**req.view_args)
  File "/workspace/whaaats_new/chatbot.py", line 95, in Message
    brand = pd.read_csv("entity_brand.csv")
UnboundLocalError: local variable 'dataSend' referenced before assignment
172.17.0.1 - - [16/Jan/2021 10:41:59] "[35m[1mPOST /message HTTP/1.1[0m" 500 -
[2021-01-16 10:44:08,264] ERROR in app: Exception on /message [POST]
Traceback (most recent call last):
  File "/usr/local/lib/python3.7/site-packages/flask/app.py", line 2447, in wsgi_app
    response = self.full_dispatch_request()
  File "/usr/local/lib/python3.7/site-packages/flask/app.py", line 1952, in full_dispatch_request
    rv = self.handle_user_exception(e)
  File "/usr/local/lib/python3.7/site-packages/flask/app.py", line 1821, in handle_user_exception
    reraise(exc_type, exc_value, tb)
  File "/usr/local/lib/python3.7/site-packages/flask/_compat.py", line 39, in reraise
    raise value
  File "/usr/local/lib/python3.7/site-packages/flask/app.py", line 1950, in full_dispatch_request
    rv = self.dispatch_request()
  File "/usr/local/lib/python3.7/site-packages/flask/app.py", line 1936, in dispatch_request
    return self.view_functions[rule.endpoint](**req.view_args)
  File "/workspace/whaaats_new/chatbot.py", line 95, in Message
    brand = pd.read_csv("entity_brand.csv")
UnboundLocalError: local variable 'dataSend' referenced before assignment
172.17.0.1 - - [16/Jan/2021 10:44:08] "[35m[1mPOST /message HTTP/1.1[0m" 500 -
172.17.0.1 - - [16/Jan/2021 10:44:16] "[37mPOST /message HTTP/1.1[0m" 200 -
[2021-01-16 10:47:15,034] ERROR in app: Exception on /message [POST]
Traceback (most recent call last):
  File "/usr/local/lib/python3.7/site-packages/flask/app.py", line 2447, in wsgi_app
    response = self.full_dispatch_request()
  File "/usr/local/lib/python3.7/site-packages/flask/app.py", line 1952, in full_dispatch_request
    rv = self.handle_user_exception(e)
  File "/usr/local/lib/python3.7/site-packages/flask/app.py", line 1821, in handle_user_exception
    reraise(exc_type, exc_value, tb)
  File "/usr/local/lib/python3.7/site-packages/flask/_compat.py", line 39, in reraise
    raise value
  File "/usr/local/lib/python3.7/site-packages/flask/app.py", line 1950, in full_dispatch_request
    rv = self.dispatch_request()
  File "/usr/local/lib/python3.7/site-packages/flask/app.py", line 1936, in dispatch_request
    return self.view_functions[rule.endpoint](**req.view_args)
  File "/workspace/whaaats_new/chatbot.py", line 95, in Message
    brand = pd.read_csv("entity_brand.csv")
UnboundLocalError: local variable 'dataSend' referenced before assignment
172.17.0.1 - - [16/Jan/2021 10:47:15] "[35m[1mPOST /message HTTP/1.1[0m" 500 -
[2021-01-16 10:47:19,209] ERROR in app: Exception on /message [POST]
Traceback (most recent call last):
  File "/usr/local/lib/python3.7/site-packages/flask/app.py", line 2447, in wsgi_app
    response = self.full_dispatch_request()
  File "/usr/local/lib/python3.7/site-packages/flask/app.py", line 1952, in full_dispatch_request
    rv = self.handle_user_exception(e)
  File "/usr/local/lib/python3.7/site-packages/flask/app.py", line 1821, in handle_user_exception
    reraise(exc_type, exc_value, tb)
  File "/usr/local/lib/python3.7/site-packages/flask/_compat.py", line 39, in reraise
    raise value
  File "/usr/local/lib/python3.7/site-packages/flask/app.py", line 1950, in full_dispatch_request
    rv = self.dispatch_request()
  File "/usr/local/lib/python3.7/site-packages/flask/app.py", line 1936, in dispatch_request
    return self.view_functions[rule.endpoint](**req.view_args)
  File "/workspace/whaaats_new/chatbot.py", line 95, in Message
    brand = pd.read_csv("entity_brand.csv")
UnboundLocalError: local variable 'dataSend' referenced before assignment
172.17.0.1 - - [16/Jan/2021 10:47:19] "[35m[1mPOST /message HTTP/1.1[0m" 500 -
[2021-01-16 10:47:19,763] ERROR in app: Exception on /message [POST]
Traceback (most recent call last):
  File "/usr/local/lib/python3.7/site-packages/flask/app.py", line 2447, in wsgi_app
    response = self.full_dispatch_request()
  File "/usr/local/lib/python3.7/site-packages/flask/app.py", line 1952, in full_dispatch_request
    rv = self.handle_user_exception(e)
  File "/usr/local/lib/python3.7/site-packages/flask/app.py", line 1821, in handle_user_exception
    reraise(exc_type, exc_value, tb)
  File "/usr/local/lib/python3.7/site-packages/flask/_compat.py", line 39, in reraise
    raise value
  File "/usr/local/lib/python3.7/site-packages/flask/app.py", line 1950, in full_dispatch_request
    rv = self.dispatch_request()
  File "/usr/local/lib/python3.7/site-packages/flask/app.py", line 1936, in dispatch_request
    return self.view_functions[rule.endpoint](**req.view_args)
  File "/workspace/whaaats_new/chatbot.py", line 95, in Message
    brand = pd.read_csv("entity_brand.csv")
UnboundLocalError: local variable 'dataSend' referenced before assignment
172.17.0.1 - - [16/Jan/2021 10:47:19] "[35m[1mPOST /message HTTP/1.1[0m" 500 -
[2021-01-16 10:50:17,437] ERROR in app: Exception on /message [POST]
Traceback (most recent call last):
  File "/usr/local/lib/python3.7/site-packages/flask/app.py", line 2447, in wsgi_app
    response = self.full_dispatch_request()
  File "/usr/local/lib/python3.7/site-packages/flask/app.py", line 1952, in full_dispatch_request
    rv = self.handle_user_exception(e)
  File "/usr/local/lib/python3.7/site-packages/flask/app.py", line 1821, in handle_user_exception
    reraise(exc_type, exc_value, tb)
  File "/usr/local/lib/python3.7/site-packages/flask/_compat.py", line 39, in reraise
    raise value
  File "/usr/local/lib/python3.7/site-packages/flask/app.py", line 1950, in full_dispatch_request
    rv = self.dispatch_request()
  File "/usr/local/lib/python3.7/site-packages/flask/app.py", line 1936, in dispatch_request
    return self.view_functions[rule.endpoint](**req.view_args)
  File "/workspace/whaaats_new/chatbot.py", line 95, in Message
    brand = pd.read_csv("entity_brand.csv")
UnboundLocalError: local variable 'dataSend' referenced before assignment
172.17.0.1 - - [16/Jan/2021 10:50:17] "[35m[1mPOST /message HTTP/1.1[0m" 500 -
[2021-01-16 10:52:18,956] ERROR in app: Exception on /message [POST]
Traceback (most recent call last):
  File "/usr/local/lib/python3.7/site-packages/flask/app.py", line 2447, in wsgi_app
    response = self.full_dispatch_request()
  File "/usr/local/lib/python3.7/site-packages/flask/app.py", line 1952, in full_dispatch_request
    rv = self.handle_user_exception(e)
  File "/usr/local/lib/python3.7/site-packages/flask/app.py", line 1821, in handle_user_exception
    reraise(exc_type, exc_value, tb)
  File "/usr/local/lib/python3.7/site-packages/flask/_compat.py", line 39, in reraise
    raise value
  File "/usr/local/lib/python3.7/site-packages/flask/app.py", line 1950, in full_dispatch_request
    rv = self.dispatch_request()
  File "/usr/local/lib/python3.7/site-packages/flask/app.py", line 1936, in dispatch_request
    return self.view_functions[rule.endpoint](**req.view_args)
  File "/workspace/whaaats_new/chatbot.py", line 95, in Message
    brand = pd.read_csv("entity_brand.csv")
UnboundLocalError: local variable 'dataSend' referenced before assignment
172.17.0.1 - - [16/Jan/2021 10:52:18] "[35m[1mPOST /message HTTP/1.1[0m" 500 -
[2021-01-16 10:52:30,658] ERROR in app: Exception on /message [POST]
Traceback (most recent call last):
  File "/usr/local/lib/python3.7/site-packages/flask/app.py", line 2447, in wsgi_app
    response = self.full_dispatch_request()
  File "/usr/local/lib/python3.7/site-packages/flask/app.py", line 1952, in full_dispatch_request
    rv = self.handle_user_exception(e)
  File "/usr/local/lib/python3.7/site-packages/flask/app.py", line 1821, in handle_user_exception
    reraise(exc_type, exc_value, tb)
  File "/usr/local/lib/python3.7/site-packages/flask/_compat.py", line 39, in reraise
    raise value
  File "/usr/local/lib/python3.7/site-packages/flask/app.py", line 1950, in full_dispatch_request
    rv = self.dispatch_request()
  File "/usr/local/lib/python3.7/site-packages/flask/app.py", line 1936, in dispatch_request
    return self.view_functions[rule.endpoint](**req.view_args)
  File "/workspace/whaaats_new/chatbot.py", line 95, in Message
    brand = pd.read_csv("entity_brand.csv")
UnboundLocalError: local variable 'dataSend' referenced before assignment
172.17.0.1 - - [16/Jan/2021 10:52:30] "[35m[1mPOST /message HTTP/1.1[0m" 500 -
[2021-01-16 10:54:23,602] ERROR in app: Exception on /message [POST]
Traceback (most recent call last):
  File "/usr/local/lib/python3.7/site-packages/flask/app.py", line 2447, in wsgi_app
    response = self.full_dispatch_request()
  File "/usr/local/lib/python3.7/site-packages/flask/app.py", line 1952, in full_dispatch_request
    rv = self.handle_user_exception(e)
  File "/usr/local/lib/python3.7/site-packages/flask/app.py", line 1821, in handle_user_exception
    reraise(exc_type, exc_value, tb)
  File "/usr/local/lib/python3.7/site-packages/flask/_compat.py", line 39, in reraise
    raise value
  File "/usr/local/lib/python3.7/site-packages/flask/app.py", line 1950, in full_dispatch_request
    rv = self.dispatch_request()
  File "/usr/local/lib/python3.7/site-packages/flask/app.py", line 1936, in dispatch_request
    return self.view_functions[rule.endpoint](**req.view_args)
  File "/workspace/whaaats_new/chatbot.py", line 95, in Message
    brand = pd.read_csv("entity_brand.csv")
UnboundLocalError: local variable 'dataSend' referenced before assignment
172.17.0.1 - - [16/Jan/2021 10:54:23] "[35m[1mPOST /message HTTP/1.1[0m" 500 -
[2021-01-16 10:54:29,551] ERROR in app: Exception on /message [POST]
Traceback (most recent call last):
  File "/usr/local/lib/python3.7/site-packages/flask/app.py", line 2447, in wsgi_app
    response = self.full_dispatch_request()
  File "/usr/local/lib/python3.7/site-packages/flask/app.py", line 1952, in full_dispatch_request
    rv = self.handle_user_exception(e)
  File "/usr/local/lib/python3.7/site-packages/flask/app.py", line 1821, in handle_user_exception
    reraise(exc_type, exc_value, tb)
  File "/usr/local/lib/python3.7/site-packages/flask/_compat.py", line 39, in reraise
    raise value
  File "/usr/local/lib/python3.7/site-packages/flask/app.py", line 1950, in full_dispatch_request
    rv = self.dispatch_request()
  File "/usr/local/lib/python3.7/site-packages/flask/app.py", line 1936, in dispatch_request
    return self.view_functions[rule.endpoint](**req.view_args)
  File "/workspace/whaaats_new/chatbot.py", line 95, in Message
    brand = pd.read_csv("entity_brand.csv")
UnboundLocalError: local variable 'dataSend' referenced before assignment
172.17.0.1 - - [16/Jan/2021 10:54:29] "[35m[1mPOST /message HTTP/1.1[0m" 500 -
 * Serving Flask app "chatbot" (lazy loading)
 * Environment: production
   WARNING: This is a development server. Do not use it in a production deployment.
   Use a production WSGI server instead.
 * Debug mode: off
 * Running on http://0.0.0.0:5000/ (Press CTRL+C to quit)
172.17.0.1 - - [16/Jan/2021 10:56:35] "[37mPOST /message HTTP/1.1[0m" 200 -
172.17.0.1 - - [16/Jan/2021 10:57:20] "[37mPOST /message HTTP/1.1[0m" 200 -
172.17.0.1 - - [16/Jan/2021 10:57:23] "[37mPOST /message HTTP/1.1[0m" 200 -
172.17.0.1 - - [16/Jan/2021 11:36:42] "[37mPOST /message HTTP/1.1[0m" 200 -
172.17.0.1 - - [16/Jan/2021 13:02:38] "[37mPOST /message HTTP/1.1[0m" 200 -
172.17.0.1 - - [19/Jan/2021 10:29:39] "[37mPOST /message HTTP/1.1[0m" 200 -
172.17.0.1 - - [19/Jan/2021 10:29:47] "[37mPOST /message HTTP/1.1[0m" 200 -
172.17.0.1 - - [22/Jan/2021 05:53:33] "[37mPOST /message HTTP/1.1[0m" 200 -
172.17.0.1 - - [22/Jan/2021 05:53:40] "[37mPOST /message HTTP/1.1[0m" 200 -
172.17.0.1 - - [22/Jan/2021 05:53:49] "[37mPOST /message HTTP/1.1[0m" 200 -
172.17.0.1 - - [22/Jan/2021 05:56:15] "[37mPOST /message HTTP/1.1[0m" 200 -
172.17.0.1 - - [22/Jan/2021 05:57:57] "[37mPOST /message HTTP/1.1[0m" 200 -
172.17.0.1 - - [23/Jan/2021 08:54:13] "[37mPOST /message HTTP/1.1[0m" 200 -
172.17.0.1 - - [23/Jan/2021 10:12:50] "[37mPOST /message HTTP/1.1[0m" 200 -
172.17.0.1 - - [23/Jan/2021 10:12:57] "[37mPOST /message HTTP/1.1[0m" 200 -
172.17.0.1 - - [25/Jan/2021 03:55:02] "[37mPOST /message HTTP/1.1[0m" 200 -
172.17.0.1 - - [25/Jan/2021 08:37:24] "[37mPOST /message HTTP/1.1[0m" 200 -
172.17.0.1 - - [30/Jan/2021 09:15:21] "[37mPOST /message HTTP/1.1[0m" 200 -
172.17.0.1 - - [30/Jan/2021 09:15:39] "[37mPOST /message HTTP/1.1[0m" 200 -
172.17.0.1 - - [03/Feb/2021 04:04:59] "[37mPOST /message HTTP/1.1[0m" 200 -
172.17.0.1 - - [07/Feb/2021 14:42:24] "[37mPOST /message HTTP/1.1[0m" 200 -
172.17.0.1 - - [07/Feb/2021 14:42:32] "[37mPOST /message HTTP/1.1[0m" 200 -
172.17.0.1 - - [19/Feb/2021 13:00:08] "[37mPOST /message HTTP/1.1[0m" 200 -
172.17.0.1 - - [19/Feb/2021 15:29:07] "[37mPOST /message HTTP/1.1[0m" 200 -
172.17.0.1 - - [19/Feb/2021 15:29:15] "[37mPOST /message HTTP/1.1[0m" 200 -
172.17.0.1 - - [19/Feb/2021 15:29:19] "[37mPOST /message HTTP/1.1[0m" 200 -
172.17.0.1 - - [19/Feb/2021 15:29:24] "[37mPOST /message HTTP/1.1[0m" 200 -
172.17.0.1 - - [21/Feb/2021 01:34:34] "[37mPOST /message HTTP/1.1[0m" 200 -
172.17.0.1 - - [21/Feb/2021 09:11:11] "[37mPOST /message HTTP/1.1[0m" 200 -
172.17.0.1 - - [21/Feb/2021 09:11:15] "[37mPOST /message HTTP/1.1[0m" 200 -
172.17.0.1 - - [21/Feb/2021 09:15:44] "[37mPOST /message HTTP/1.1[0m" 200 -
172.17.0.1 - - [21/Feb/2021 09:17:01] "[37mPOST /message HTTP/1.1[0m" 200 -
172.17.0.1 - - [21/Feb/2021 09:17:03] "[37mPOST /message HTTP/1.1[0m" 200 -
172.17.0.1 - - [22/Feb/2021 04:12:01] "[37mPOST /message HTTP/1.1[0m" 200 -
172.17.0.1 - - [22/Feb/2021 13:21:47] "[37mPOST /message HTTP/1.1[0m" 200 -
172.17.0.1 - - [11/Mar/2021 05:21:51] "[37mPOST /message HTTP/1.1[0m" 200 -
172.17.0.1 - - [11/Mar/2021 05:22:48] "[37mPOST /message HTTP/1.1[0m" 200 -
172.17.0.1 - - [15/Mar/2021 13:44:30] "[37mPOST /message HTTP/1.1[0m" 200 -
172.17.0.1 - - [15/Mar/2021 13:44:41] "[37mPOST /message HTTP/1.1[0m" 200 -
172.17.0.1 - - [15/Mar/2021 13:44:46] "[37mPOST /message HTTP/1.1[0m" 200 -
172.17.0.1 - - [15/Mar/2021 13:44:56] "[37mPOST /message HTTP/1.1[0m" 200 -
172.17.0.1 - - [15/Mar/2021 13:45:05] "[37mPOST /message HTTP/1.1[0m" 200 -
